Workbook

Sheet Informe Financiero Semanal
A1: INFORME FINANCIERO SEMANAL
A2: GLOBAL SOLUTIONS SPA — AL 7 AGO 2026
A4: 1. SALDO DE CAJA HOY
A5: Concepto | B5: Monto
A6: Banco Santander | B6: ='Memoria de Cálculo'!$B$7 -> 303760
A7: Aramco (real: $4.977 gasolina + $91.430 diésel) | B7: ='Memoria de Cálculo'!$B$8 -> 96407
A8: TOTAL SALDO DISPONIBLE | B8: =B6+B7 -> 400167
A10: 2. VENTAS C/IVA POR SERVICIOS — AGOSTO al 07-08-2026
A11: Cliente | B11: Ejecutado según sistema | C11: (GPS confirma actividad real)
A12: Sollem SpA | B12: ='Memoria de Cálculo'!$B$11*(1+'Memoria de Cálculo'!$B$4) -> 4578590.5 | C12: ='Memoria de Cálculo'!$B$12*(1+'Memoria de Cálculo'!$B$4) -> 1989493.2
A13: Citrus Agro | B13: ='Memoria de Cálculo'!$B$13*(1+'Memoria de Cálculo'!$B$4) -> 573144.46 | C13: ='Memoria de Cálculo'!$B$14*(1+'Memoria de Cálculo'!$B$4) -> 685484.03
A14: Presmita | B14: ='Memoria de Cálculo'!$B$15*(1+'Memoria de Cálculo'!$B$4) -> 535500 | C14: ='Memoria de Cálculo'!$B$16*(1+'Memoria de Cálculo'!$B$4) -> 535500
A15: Trans Luciano | B15: ='Memoria de Cálculo'!$B$17*(1+'Memoria de Cálculo'!$B$4) -> 499800 | C15: ='Memoria de Cálculo'!$B$18*(1+'Memoria de Cálculo'!$B$4) -> 0
A16: TOTAL VENTAS REALES AGOSTO | B16: =SUM(B12:B15) -> 6187034.9 | C16: =SUM(C12:C15) -> 3210477.2
A17: TOTAL GENERAL | B17: =B16+C16 -> 9397512.1
A19: 3. EGRESOS CARTOLA SANTANDER — AGOSTO (01 al 07-08-2026, caja real)
A20: Categoría | B20: Monto
A21: Combustible (Aramco+Copec vía cartola) | B21: ='Memoria de Cálculo'!$B$21 -> 2600000
A22: Remuneraciones | B22: ='Memoria de Cálculo'!$B$22 -> 4193196
A23: Repuestos / Mantención | B23: ='Memoria de Cálculo'!$B$23 -> 87453
A24: Viáticos y Peajes | B24: ='Memoria de Cálculo'!$B$24 -> 0
A25: Otros sin clasificar | B25: ='Memoria de Cálculo'!$B$25 -> 1257072
A26: Transferencia interna | B26: ='Memoria de Cálculo'!$B$26 -> 50000
A27: TOTAL EGRESOS | B27: =SUM(B21:B26) -> 8187721
A29: 4. FACTURAS — AGOSTO 2026
A30: Concepto | B30: Monto
A31: Facturas emitidas (folio 30, Sollem, bruto) | B31: ='Memoria de Cálculo'!$B$29 -> 624512
A32: Facturas pagadas en cuenta (neto, factoring INCOFIN 04-08) | B32: ='Memoria de Cálculo'!$B$30 -> 605464
A33: Facturas emitidas pendientes de pago | B33: ='Memoria de Cálculo'!$B$31 -> 0
A34: Facturas por emitir (= Total Ventas Agosto — folio 30 es cierre de JULIO, no se resta) | B34: =B17 -> 9397512.1
A35: - Sollem SpA | B35: =('Memoria de Cálculo'!$B$11+'Memoria de Cálculo'!$B$12)*(1+'Memoria de Cálculo'!$B$4) -> 6568083.6
A36: - Citrus Agro | B36: =('Memoria de Cálculo'!$B$13+'Memoria de Cálculo'!$B$14)*(1+'Memoria de Cálculo'!$B$4) -> 1258628.5
A37: - Presmita | B37: =('Memoria de Cálculo'!$B$15+'Memoria de Cálculo'!$B$16)*(1+'Memoria de Cálculo'!$B$4) -> 1071000
A38: - Trans Luciano | B38: =('Memoria de Cálculo'!$B$17+'Memoria de Cálculo'!$B$18)*(1+'Memoria de Cálculo'!$B$4) -> 499800
A40: 5. FACTURAS EMITIDAS JULIO, SIN PAGO EN CARTOLA (julio ni agosto)
A41: Cliente | B41: Fecha Emisión | C41: Monto (con IVA)
A42: Danilo Enrique Núñez Osorio - Factura 24 | B42: 25-07-2026 | C42: ='Memoria de Cálculo'!$B$34 -> 690200
A43: Presmita - Factura 27 | B43: 30-07-2026 | C43: ='Memoria de Cálculo'!$B$35 -> 1428000
A44: TOTAL SIN PAGAR | C44: =C42+C43 -> 2118200
A46: NOTA IMPORTANTE
...

Sheet Memoria de Cálculo
A1: MEMORIA DE CÁLCULO — Informe Financiero Semanal al 07-08-2026
A3: SUPUESTO GENERAL
A4: Tasa IVA | B4: 0.19
A6: SALDO DE CAJA (real)
A7: Banco Santander | B7: 303760 | C7: Cartola N°4, saldo final al 07-08-2026
A8: Aramco | B8: 96407 | C8: Portal Esmax: $4.977 gasolina + $91.430 diésel, real 07-08-2026
A10: VENTAS NETAS POR SERVICIO — AGOSTO (servicios_piloto, sin IVA)
A11: Sollem SpA — Ejecutado (neto) | B11: 3847555 | C11: servicios_piloto, estado=ejecutado
A12: Sollem SpA — Asignado (neto, GPS confirma actividad real) | B12: 1671843 | C12: servicios_piloto estado=asignado, validado con export GPS
A13: Citrus Agro — Ejecutado (neto) | B13: 481634 | C13: servicios_piloto, estado=ejecutado
A14: Citrus Agro — Asignado (neto, GPS confirma actividad real) | B14: 576037 | C14: servicios_piloto estado=asignado, validado con export GPS
A15: Presmita — Ejecutado (neto) | B15: 450000 | C15: servicios_piloto, estado=ejecutado
A16: Presmita — Asignado (neto, GPS confirma actividad real) | B16: 450000 | C16: servicios_piloto estado=asignado, validado con export GPS
A17: Trans Luciano — Ejecutado (neto) | B17: 420000 | C17: servicios_piloto, estado=ejecutado
A18: Trans Luciano — Asignado (neto, GPS confirma actividad real) | B18: 0 | C18: servicios_piloto estado=asignado, validado con export GPS
A20: EGRESOS CARTOLA SANTANDER — AGOSTO (01 al 07-08-2026, real, kaptura_caja)
A21: Combustible (Aramco+Copec vía cartola) | B21: 2600000 | C21: kaptura_caja, categorización real cruzada RCV
A22: Remuneraciones | B22: 4193196 | C22: kaptura_caja, categorización real cruzada RCV
A23: Repuestos / Mantención | B23: 87453 | C23: kaptura_caja, categorización real cruzada RCV
A24: Viáticos y Peajes | B24: 0 | C24: kaptura_caja, categorización real cruzada RCV
A25: Otros sin clasificar | B25: 1257072 | C25: kaptura_caja, categorización real cruzada RCV
A26: Transferencia interna | B26: 50000 | C26: kaptura_caja, categorización real cruzada RCV
A28: FACTURAS — AGOSTO 2026
A29: Facturas emitidas — folio 30 Sollem (bruto) | B29: 624512 | C29: RCV Venta agosto. CONFIRMADO con factura PDF: es cierre de JULIO (GDs 24342,24343), no venta de agosto — no se resta de Ventas Agosto
A30: Facturas pagadas en cuenta (neto, factoring) | B30: 605464 | C30: INCOFIN S.A., cartola 04-08-2026
A31: Facturas emitidas pendientes de pago (agosto) | B31: 0 | C31: Folio 30 quedó 100% liquidado vía factoring — el descuento de factoring es costo financiero, no saldo impago
A33: FACTURAS EMITIDAS JULIO, SIN PAGO EN CARTOLA (julio ni agosto)
A34: Danilo Enrique Núñez Osorio — Factura 24 (con IVA) | B34: 690200 | C34: RCV Venta junio, folio 24, emitida 25-07-2026. Sin match en kaptura_caja jul/ago
A35: Presmita — Factura 27 (con IVA) | B35: 1428000 | C35: RCV Venta julio, folio 27, emitida 30-07-2026. Sin match en kaptura_caja jul/ago
