Workbook

Sheet Presupuesto
A1: PRESUPUESTO — PARAMETROS FIJOS — AGOSTO 2026
A3: Parametro | B3: Valor | C3: Nota
A5: SueldoConductorMes | B5: 660000
A6: ComisionConductorPct | B6: 0.08
A7: ViaticoDia | B7: 12000
A8: CoordinadorOperaciones | B8: 1500000
A9: AyudanteOperaciones | B9: 900000
A10: AdministrativoControlGestion | B10: 500000
A11: Arriendo | B11: 450000
A12: Contabilidad | B12: 50000
A13: GastosComunes | B13: 100000
A14: Permisos | B14: 0
A15: ProvisionFiniquitos | B15: 0
A16: UFVigente | B16: 40873 | C16: Al 31-ago-2026
A17: UmbralB_UF | B17: 8000
A18: UmbralC_UF | B18: 20000
A19: ImpEspecificoPorLitro | B19: 102
A20: DiasHabilesMes | B20: 21 | C20: Agosto: 31 dias, 10 fin de semana
A21: FactorIVA | B21: 1.19

Sheet Financiero
A1: INFORME EJECUTIVO — AMBITO FINANCIERO — AGOSTO 2026
A2: Formulas vivas. Mismo criterio y estructura que julio.
A4: Concepto | C4: Monto
A5: RENTABILIDAD
A6: Ventas netas reales | C6: =C8+C9+C10+C11+C12+C13+C14 -> 27879313
A7: Ventas por equipo:
A8: DVDS36 | C8: =SUMIFS('Datos - Servicios Ago'!$G$4:$G$75,'Datos - Servicios Ago'!$J$4:$J$75,"DVDS36") -> 3520840.3
A9: GCFF12 | C9: =SUMIFS('Datos - Servicios Ago'!$G$4:$G$75,'Datos - Servicios Ago'!$J$4:$J$75,"GCFF12") -> 8369328
A10: GKFD84 | C10: =SUMIFS('Datos - Servicios Ago'!$G$4:$G$75,'Datos - Servicios Ago'!$J$4:$J$75,"GKFD84") -> 7992732.3
A11: WR9192 | C11: =SUMIFS('Datos - Servicios Ago'!$G$4:$G$75,'Datos - Servicios Ago'!$J$4:$J$75,"WR9192") -> 687305
A12: XR8555 | C12: =SUMIFS('Datos - Servicios Ago'!$G$4:$G$75,'Datos - Servicios Ago'!$J$4:$J$75,"XR8555") -> 7095467.9
A13: BPLB35 | C13: =SUMIFS('Datos - Servicios Ago'!$G$4:$G$75,'Datos - Servicios Ago'!$J$4:$J$75,"BPLB35") -> 0
A14: Comision por terceros (10% s/ $2.136.395 facturado por terceros -- Global sin costo, pendiente corroborar desfase sept.) | C14: 213640
A15: Costos de operacion | C15: =C16+C29+C46+C52 -> 21031021
A16: 1. Combustible y costos de ruta | C16: =C18-C27+C28 -> 10177072
A17: Combustible bruto (con IVA) | C17: =SUMIFS('Datos - Cartola Ago'!$D$4:$D$179,'Datos - Cartola Ago'!$C$4:$C$179,"combustible",'Datos - Cartola Ago'!$B$4:$B$179,"egreso") -> 11761000
A18: Combustible neto IVA | C18: =C17/Presupuesto!$B$21 -> 9883193.3
A19: Venta anual proyectada (mes x 12) | C19: =C6*12 -> 3.3455176e+08
A20: UF vigente | C20: =Presupuesto!$B$16 -> 40873
A21: Venta anual proyectada en UF | C21: =C19/C20 -> 8185.1531
A22: Umbral B UF/año | C22: =Presupuesto!$B$17 -> 8000
A23: Umbral C UF/año | C23: =Presupuesto!$B$18 -> 20000
A24: % Devolucion imp. especifico | C24: =IF(C21<=2400,0.8,IF(C21<=C22,0.7,IF(C21<=C23,0.525,0.31))) -> 0.525
A25: Componente base imp. especifico | C25: =Presupuesto!$B$19 -> 102
A26: Litros agosto (camiones+camionetas) | C26: =SUM('Datos - Combustible y GPS Ago'!C4:C10) -> 10042.3
A27: Devolucion impuesto especifico diesel | C27: =C26*C25*C24 -> 537765.17
A28: Peajes (real concesionarias GKFD84+KSRC78, resto sin peaje en agosto) | C28: 831644
A29: 2. Remuneraciones | C29: =C30+C34+C38+C42 -> 6631538.8
A30: 2.1 Felipe Madariaga (conductor) | C30: =C31+C32+C33 -> 2047838.9
A31: Sueldo | C31: =SUMIFS('Datos - Cartola Ago'!$D$4:$D$179,'Datos - Cartola Ago'!$C$4:$C$179,"sueldo_conductor",'Datos - Cartola Ago'!$E$4:$E$179,"*Madaria*") -> 1254600
A32: Comision 8% sobre sus ventas netas | C32: =SUMIFS('Datos - Servicios Ago'!$G$4:$G$75,'Datos - Servicios Ago'!$I$4:$I$75,"*Madaria*")*Presupuesto!$B$6 -> 685238.9
A33: Viatico (dias confirmados GPS) | C33: =Presupuesto!$B$7*SUMIFS('Datos - Servicios Ago'!$L$4:$L$75,'Datos - Servicios Ago'!$I$4:$I$75,"*Madaria*") -> 108000
A34: 2.2 Francisco Mancilla (conductor) | C34: =C35+C36+C37 -> 2378898.3
A35: Sueldo | C35: =SUMIFS('Datos - Cartola Ago'!$D$4:$D$179,'Datos - Cartola Ago'!$C$4:$C$179,"sueldo_conductor",'Datos - Cartola Ago'!$E$4:$E$179,"*Manc*") -> 1535100
A36: Comision 8% sobre sus ventas netas | C36: =SUMIFS('Datos - Servicios Ago'!$G$4:$G$75,'Datos - Servicios Ago'!$I$4:$I$75,"*Manc*")*Presupuesto!$B$6 -> 699798.34
A37: Viatico (dias confirmados GPS) | C37: =Presupuesto!$B$7*SUMIFS('Datos - Servicios Ago'!$L$4:$L$75,'Datos - Servicios Ago'!$I$4:$I$75,"*Manc*") -> 144000
A38: 2.3 Manuel Madrid (conductor) | C38: =C39+C40+C41 -> 2204801.5
A39: Sueldo | C39: =SUMIFS('Datos - Cartola Ago'!$D$4:$D$179,'Datos - Cartola Ago'!$C$4:$C$179,"sueldo_conductor",'Datos - Cartola Ago'!$E$4:$E$179,"*Madrid*") -> 1436000
A40: Comision 8% sobre sus ventas netas | C40: =SUMIFS('Datos - Servicios Ago'!$G$4:$G$75,'Datos - Servicios Ago'!$I$4:$I$75,"*Madrid*")*Presupuesto!$B$6 -> 576801.51
A41: Viatico (dias confirmados GPS) | C41: =Presupuesto!$B$7*SUMIFS('Datos - Servicios Ago'!$L$4:$L$75,'Datos - Servicios Ago'!$I$4:$I$75,"*Madrid*") -> 192000
...

Sheet Comercial
A1: INFORME EJECUTIVO — AMBITO COMERCIAL — AGOSTO 2026
A4: PILAR 1 — DISTRIBUCION / CONCENTRACION DE CARTERA
A5: Cliente | B5: Ventas agosto | C5: % de la cartera
A6: Sollem | B6: 22906855 | C6: =B6/$B$14 -> 0.64591012
A7: Serlog | B7: 3614314 | C7: =B7/$B$14 -> 0.10191368
A8: Nano Presmita | B8: 3600000 | C8: =B8/$B$14 -> 0.10151007
A9: Trans Luciano | B9: 2249100 | C9: =B9/$B$14 -> 0.063418416
A10: Don Hugo | B10: 1080000 | C10: =B10/$B$14 -> 0.030453021
A11: Trast | B11: 817893 | C11: =B11/$B$14 -> 0.023062326
A12: Alfa Yam | B12: 779800 | C12: =B12/$B$14 -> 0.021988209
A13: Ivan Arriaza | B13: 416500 | C13: =B13/$B$14 -> 0.011744151
A14: TOTAL | B14: =SUM(B6:B13) -> 35464462
A16: Sollem sube a 64,6% de la cartera en agosto (vs 50% en julio) -- concentracion aumento.
A18: PILAR 2 — FIDELIZACION
A19: Cliente | B19: Antiguedad (desde) | C19: Meses con actividad
A20: Sollem SpA | B20: 2026-05-04 | C20: 5
A21: Presmita | B21: 2026-05-07 | C21: 5
A22: Serlogin | B22: 2026-06-09 | C22: 3
A23: Trans Luciano | B23: 2026-07-28 | C23: 3
A24: Don Hugo | B24: 2026-08 | C24: 1
A25: Trast | B25: 2026-08 | C25: 1
A26: Alfa Jam | B26: 2026-08-11 | C26: 2
A28: PILAR 3 — DIVERSIFICACION
A29: Clientes activos en agosto | B29: 8
A30: Clientes nuevos en agosto | B30: Don Hugo, Trast (primer servicio)
A31: % dependencia Sollem | B31: =B6/B14 -> 0.64591012

Sheet Operacional
A1: INFORME EJECUTIVO — AMBITO OPERACIONAL — AGOSTO 2026
A4: COMBUSTIBLE — camiones + camionetas (Aramco+Copec)
A5: Patente | B5: Tipo | C5: Litros | D5: Monto $ | E5: % del total
A6: ='Datos - Combustible y GPS Ago'!A4 -> DVDS36 | B6: ='Datos - Combustible y GPS Ago'!B4 -> Camión | C6: ='Datos - Combustible y GPS Ago'!C4 -> 1150.1 | D6: ='Datos - Combustible y GPS Ago'!D4 -> 1409841 | E6: =D6/SUM('Datos - Combustible y GPS Ago'!D4:D10) -> 0.11357673
A7: ='Datos - Combustible y GPS Ago'!A5 -> GCFF12 | B7: ='Datos - Combustible y GPS Ago'!B5 -> Camión | C7: ='Datos - Combustible y GPS Ago'!C5 -> 3031.3 | D7: ='Datos - Combustible y GPS Ago'!D5 -> 3736980 | E7: =D7/SUM('Datos - Combustible y GPS Ago'!D4:D10) -> 0.30105094
A8: ='Datos - Combustible y GPS Ago'!A6 -> GKFD84 | B8: ='Datos - Combustible y GPS Ago'!B6 -> Camión | C8: ='Datos - Combustible y GPS Ago'!C6 -> 2987 | D8: ='Datos - Combustible y GPS Ago'!D6 -> 3663449 | E8: =D8/SUM('Datos - Combustible y GPS Ago'!D4:D10) -> 0.29512729
A9: ='Datos - Combustible y GPS Ago'!A7 -> KSRC78 | B9: ='Datos - Combustible y GPS Ago'!B7 -> Camioneta | C9: ='Datos - Combustible y GPS Ago'!C7 -> 714.8 | D9: ='Datos - Combustible y GPS Ago'!D7 -> 907953 | E9: =D9/SUM('Datos - Combustible y GPS Ago'!D4:D10) -> 0.073144654
A10: ='Datos - Combustible y GPS Ago'!A8 -> WR9192 | B10: ='Datos - Combustible y GPS Ago'!B8 -> Camión | C10: ='Datos - Combustible y GPS Ago'!C8 -> 1558.6 | D10: ='Datos - Combustible y GPS Ago'!D8 -> 1973411 | E10: =D10/SUM('Datos - Combustible y GPS Ago'!D4:D10) -> 0.1589779
A11: ='Datos - Combustible y GPS Ago'!A9 -> XR8555 | B11: ='Datos - Combustible y GPS Ago'!B9 -> Camión | C11: ='Datos - Combustible y GPS Ago'!C9 -> 523.1 | D11: ='Datos - Combustible y GPS Ago'!D9 -> 623347 | E11: =D11/SUM('Datos - Combustible y GPS Ago'!D4:D10) -> 0.050216807
A12: ='Datos - Combustible y GPS Ago'!A10 -> JYJV21 | B12: ='Datos - Combustible y GPS Ago'!B10 -> Camioneta | C12: ='Datos - Combustible y GPS Ago'!C10 -> 77.4 | D12: ='Datos - Combustible y GPS Ago'!D10 -> 98134 | E12: =D12/SUM('Datos - Combustible y GPS Ago'!D4:D10) -> 0.0079056707
A14: RENDIMIENTO km/lt — SOLO CAMIONES
A15: Patente | B15: Litros | C15: Km GPS | D15: Rendimiento (km/lt)
A16: =IF('Datos - Combustible y GPS Ago'!B4="Camión",'Datos - Combustible y GPS Ago'!A4,"") -> DVDS36 | B16: =IF('Datos - Combustible y GPS Ago'!B4="Camión",'Datos - Combustible y GPS Ago'!C4,"") -> 1150.1 | C16: =IF(AND('Datos - Combustible y GPS Ago'!B4="Camión",ISNUMBER('Datos - Combustible y GPS Ago'!E4)),'Datos - Combustible y GPS Ago'!E4,"") -> 4373.267 | D16: =IFERROR(C16/B16,"") -> 3.8025102
A17: =IF('Datos - Combustible y GPS Ago'!B5="Camión",'Datos - Combustible y GPS Ago'!A5,"") -> GCFF12 | B17: =IF('Datos - Combustible y GPS Ago'!B5="Camión",'Datos - Combustible y GPS Ago'!C5,"") -> 3031.3 | C17: =IF(AND('Datos - Combustible y GPS Ago'!B5="Camión",ISNUMBER('Datos - Combustible y GPS Ago'!E5)),'Datos - Combustible y GPS Ago'!E5,"") -> 5299.228 | D17: =IFERROR(C17/B17,"") -> 1.7481701
A18: =IF('Datos - Combustible y GPS Ago'!B6="Camión",'Datos - Combustible y GPS Ago'!A6,"") -> GKFD84 | B18: =IF('Datos - Combustible y GPS Ago'!B6="Camión",'Datos - Combustible y GPS Ago'!C6,"") -> 2987 | C18: =IF(AND('Datos - Combustible y GPS Ago'!B6="Camión",ISNUMBER('Datos - Combustible y GPS Ago'!E6)),'Datos - Combustible y GPS Ago'!E6,"") -> 6568.06 | D18: =IFERROR(C18/B18,"") -> 2.1988818
A19: =IF('Datos - Combustible y GPS Ago'!B7="Camión",'Datos - Combustible y GPS Ago'!A7,"") | B19: =IF('Datos - Combustible y GPS Ago'!B7="Camión",'Datos - Combustible y GPS Ago'!C7,"") | C19: =IF(AND('Datos - Combustible y GPS Ago'!B7="Camión",ISNUMBER('Datos - Combustible y GPS Ago'!E7)),'Datos - Combustible y GPS Ago'!E7,"") | D19: =IFERROR(C19/B19,"")
A20: =IF('Datos - Combustible y GPS Ago'!B8="Camión",'Datos - Combustible y GPS Ago'!A8,"") -> WR9192 | B20: =IF('Datos - Combustible y GPS Ago'!B8="Camión",'Datos - Combustible y GPS Ago'!C8,"") -> 1558.6 | C20: =IF(AND('Datos - Combustible y GPS Ago'!B8="Camión",ISNUMBER('Datos - Combustible y GPS Ago'!E8)),'Datos - Combustible y GPS Ago'!E8,"") -> 112.527 | D20: =IFERROR(C20/B20,"") -> 0.072197485 | E20: SIN DATOS COMPLETOS EN GPS FORGUARD
A21: =IF('Datos - Combustible y GPS Ago'!B9="Camión",'Datos - Combustible y GPS Ago'!A9,"") -> XR8555 | B21: =IF('Datos - Combustible y GPS Ago'!B9="Camión",'Datos - Combustible y GPS Ago'!C9,"") -> 523.1 | C21: =IF(AND('Datos - Combustible y GPS Ago'!B9="Camión",ISNUMBER('Datos - Combustible y GPS Ago'!E9)),'Datos - Combustible y GPS Ago'!E9,"") -> 5338.884 | D21: =IFERROR(C21/B21,"") -> 10.20624 | E21: SIN DATOS COMPLETOS EN GPS FORGUARD
A22: =IF('Datos - Combustible y GPS Ago'!B10="Camión",'Datos - Combustible y GPS Ago'!A10,"") | B22: =IF('Datos - Combustible y GPS Ago'!B10="Camión",'Datos - Combustible y GPS Ago'!C10,"") | C22: =IF(AND('Datos - Combustible y GPS Ago'!B10="Camión",ISNUMBER('Datos - Combustible y GPS Ago'!E10)),'Datos - Combustible y GPS Ago'!E10,"") | D22: =IFERROR(C22/B22,"")
A24: MANTENCION — SOLO CAMIONES
A25: Patente (camión) | B25: Mantencion neta IVA
A26: DVDS36 | B26: =SUMIFS('Datos - Cartola Ago'!$D$4:$D$179,'Datos - Cartola Ago'!$C$4:$C$179,"mantencion",'Datos - Cartola Ago'!$B$4:$B$179,"egreso",'Datos - Cartola Ago'!$F$4:$F$179,A26)/Presupuesto!$B$21 -> 0
A27: GCFF12 | B27: =SUMIFS('Datos - Cartola Ago'!$D$4:$D$179,'Datos - Cartola Ago'!$C$4:$C$179,"mantencion",'Datos - Cartola Ago'!$B$4:$B$179,"egreso",'Datos - Cartola Ago'!$F$4:$F$179,A27)/Presupuesto!$B$21 -> 0
A28: GKFD84 | B28: =SUMIFS('Datos - Cartola Ago'!$D$4:$D$179,'Datos - Cartola Ago'!$C$4:$C$179,"mantencion",'Datos - Cartola Ago'!$B$4:$B$179,"egreso",'Datos - Cartola Ago'!$F$4:$F$179,A28)/Presupuesto!$B$21 -> 0
A29: WR9192 | B29: =SUMIFS('Datos - Cartola Ago'!$D$4:$D$179,'Datos - Cartola Ago'!$C$4:$C$179,"mantencion",'Datos - Cartola Ago'!$B$4:$B$179,"egreso",'Datos - Cartola Ago'!$F$4:$F$179,A29)/Presupuesto!$B$21 -> 0
A30: XR8555 | B30: =SUMIFS('Datos - Cartola Ago'!$D$4:$D$179,'Datos - Cartola Ago'!$C$4:$C$179,"mantencion",'Datos - Cartola Ago'!$B$4:$B$179,"egreso",'Datos - Cartola Ago'!$F$4:$F$179,A30)/Presupuesto!$B$21 -> 0
A31: TOTAL mantencion camiones | B31: =B26+B27+B28+B29+B30 -> 0
A33: OCUPACION POR EQUIPO — fuente: GPS real
A34: Dias habiles del mes | B34: =Presupuesto!$B$20 -> 21
A35: Patente | B35: Dias con GPS real | C35: % Ocupacion
A36: DVDS36 | B36: =COUNTIF('Datos - GPS Dias Ago'!$A$4:$A$88,A36) -> 18 | C36: =B36/$B$34 -> 0.85714286
A37: GCFF12 | B37: =COUNTIF('Datos - GPS Dias Ago'!$A$4:$A$88,A37) -> 20 | C37: =B37/$B$34 -> 0.95238095
A38: GKFD84 | B38: =COUNTIF('Datos - GPS Dias Ago'!$A$4:$A$88,A38) -> 20 | C38: =B38/$B$34 -> 0.95238095
A39: WR9192 | B39: =COUNTIF('Datos - GPS Dias Ago'!$A$4:$A$88,A39) -> 7 | C39: =B39/$B$34 -> 0.33333333
A40: XR8555 | B40: =COUNTIF('Datos - GPS Dias Ago'!$A$4:$A$88,A40) -> 20 | C40: =B40/$B$34 -> 0.95238095
A41: BPLB35 | B41: =COUNTIF('Datos - GPS Dias Ago'!$A$4:$A$88,A41) -> 0 | C41: =B41/$B$34 -> 0
A43: CALIDAD: sin fuente de datos disponible.

Sheet Datos - Servicios Ago
A1: SERVICIOS REALIZADOS — AGOSTO 2026
A3: Patente | B3: Fecha (Fecha GD real) | C3: Cliente | D3: Origen | E3: Destino | F3: Flete Total (bruto) | G3: Flete Neto (=Bruto/1.19) | H3: Estado Pago | I3: Conductor | J3: Patente normalizada | K3: GPS confirma ese dia | L3: Dia unico conf. GPS x conductor
A4: GCFF12 | B4: 2026-08-03 | C4: Sollem | D4: Casa Blanca | E4: Peralillo - Santa Cruz - Placilla | F4: 882869.33 | G4: =F4/1.19 -> 741907 | H4: Pendiente | I4: Francisco Mancilla | J4: =IF(A4="DSDV36","DVDS36",A4) -> GCFF12 | K4: =IF(SUMPRODUCT(('Datos - GPS Dias Ago'!$A$5:$A$88=J4)*('Datos - GPS Dias Ago'!$B$5:$B$88=TEXT(B4,"yyyy-mm-dd")))>0,1,0) -> 1 | L4: =IF(AND(COUNTIFS($I$4:I4,I4,$B$4:B4,B4)=1,K4=1),1,0) -> 1
A5: XR8555 | B5: 2026-08-03 | C5: Nano Presmita | D5: Coltauco | E5: Valparaiso | F5: 450000 | G5: =F5/1.19 -> 378151.26 | H5: Pendiente | I5: Manuel Madrid | J5: =IF(A5="DSDV36","DVDS36",A5) -> XR8555 | K5: =IF(SUMPRODUCT(('Datos - GPS Dias Ago'!$A$5:$A$88=J5)*('Datos - GPS Dias Ago'!$B$5:$B$88=TEXT(B5,"yyyy-mm-dd")))>0,1,0) -> 1 | L5: =IF(AND(COUNTIFS($I$4:I5,I5,$B$4:B5,B5)=1,K5=1),1,0) -> 1
A6: GKFD84 | B6: 2026-08-04 | C6: Sollem | D6: Casa Blanca | E6: Lampa | F6: 364633.85 | G6: =F6/1.19 -> 306415 | H6: Pendiente | I6: Felipe Madariaga | J6: =IF(A6="DSDV36","DVDS36",A6) -> GKFD84 | K6: =IF(SUMPRODUCT(('Datos - GPS Dias Ago'!$A$5:$A$88=J6)*('Datos - GPS Dias Ago'!$B$5:$B$88=TEXT(B6,"yyyy-mm-dd")))>0,1,0) -> 1 | L6: =IF(AND(COUNTIFS($I$4:I6,I6,$B$4:B6,B6)=1,K6=1),1,0) -> 1
A7: GKFD84 | B7: 2026-08-04 | C7: Sollem | D7: Casa Blanca | E7: Chimbarongo | F7: 668669.33 | G7: =F7/1.19 -> 561907 | H7: Pendiente | I7: Felipe Madariaga | J7: =IF(A7="DSDV36","DVDS36",A7) -> GKFD84 | K7: =IF(SUMPRODUCT(('Datos - GPS Dias Ago'!$A$5:$A$88=J7)*('Datos - GPS Dias Ago'!$B$5:$B$88=TEXT(B7,"yyyy-mm-dd")))>0,1,0) -> 1 | L7: =IF(AND(COUNTIFS($I$4:I7,I7,$B$4:B7,B7)=1,K7=1),1,0) -> 0
A8: XR8555 | B8: 2026-08-05 | C8: Trans Luciano | D8: Requinoa | E8: Codegua | F8: 249900 | G8: =F8/1.19 -> 210000 | H8: Pendiente | I8: Manuel Madrid | J8: =IF(A8="DSDV36","DVDS36",A8) -> XR8555 | K8: =IF(SUMPRODUCT(('Datos - GPS Dias Ago'!$A$5:$A$88=J8)*('Datos - GPS Dias Ago'!$B$5:$B$88=TEXT(B8,"yyyy-mm-dd")))>0,1,0) -> 1 | L8: =IF(AND(COUNTIFS($I$4:I8,I8,$B$4:B8,B8)=1,K8=1),1,0) -> 1
A9: XR8555 | B9: 2026-08-05 | C9: Trans Luciano | D9: Requinoa | E9: Codegua | F9: 249900 | G9: =F9/1.19 -> 210000 | H9: Pendiente | I9: Manuel Madrid | J9: =IF(A9="DSDV36","DVDS36",A9) -> XR8555 | K9: =IF(SUMPRODUCT(('Datos - GPS Dias Ago'!$A$5:$A$88=J9)*('Datos - GPS Dias Ago'!$B$5:$B$88=TEXT(B9,"yyyy-mm-dd")))>0,1,0) -> 1 | L9: =IF(AND(COUNTIFS($I$4:I9,I9,$B$4:B9,B9)=1,K9=1),1,0) -> 0
A10: GCFF12 | B10: 2026-08-05 | C10: Sollem | D10: Casa Blanca | E10: Lampa | F10: 364633.85 | G10: =F10/1.19 -> 306415 | H10: Pendiente | I10: Francisco Mancilla | J10: =IF(A10="DSDV36","DVDS36",A10) -> GCFF12 | K10: =IF(SUMPRODUCT(('Datos - GPS Dias Ago'!$A$5:$A$88=J10)*('Datos - GPS Dias Ago'!$B$5:$B$88=TEXT(B10,"yyyy-mm-dd")))>0,1,0) -> 1 | L10: =IF(AND(COUNTIFS($I$4:I10,I10,$B$4:B10,B10)=1,K10=1),1,0) -> 1
A11: GCFF12 | B11: 2026-08-05 | C11: Serlog | D11: Curacavi | E11: Quinta Tilcoco, Rauco - Sarmiento - Sagrada Familia | F11: 869222.41 | G11: =F11/1.19 -> 730439 | H11: Pendiente | I11: Francisco Mancilla | J11: =IF(A11="DSDV36","DVDS36",A11) -> GCFF12 | K11: =IF(SUMPRODUCT(('Datos - GPS Dias Ago'!$A$5:$A$88=J11)*('Datos - GPS Dias Ago'!$B$5:$B$88=TEXT(B11,"yyyy-mm-dd")))>0,1,0) -> 1 | L11: =IF(AND(COUNTIFS($I$4:I11,I11,$B$4:B11,B11)=1,K11=1),1,0) -> 0
A12: GKFD84 | B12: 2026-08-05 | C12: Sollem | D12: Casa Blanca | E12: Lampa | F12: 364633.85 | G12: =F12/1.19 -> 306415 | H12: Pendiente | I12: Felipe Madariaga | J12: =IF(A12="DSDV36","DVDS36",A12) -> GKFD84 | K12: =IF(SUMPRODUCT(('Datos - GPS Dias Ago'!$A$5:$A$88=J12)*('Datos - GPS Dias Ago'!$B$5:$B$88=TEXT(B12,"yyyy-mm-dd")))>0,1,0) -> 1 | L12: =IF(AND(COUNTIFS($I$4:I12,I12,$B$4:B12,B12)=1,K12=1),1,0) -> 1
A13: GKFD84 | B13: 2026-08-05 | C13: Sollem | D13: Casa Blanca | E13: Marchihue - Lolol - Chimbarongo | F13: 811112.33 | G13: =F13/1.19 -> 681607 | H13: Pendiente | I13: Felipe Madariaga | J13: =IF(A13="DSDV36","DVDS36",A13) -> GKFD84 | K13: =IF(SUMPRODUCT(('Datos - GPS Dias Ago'!$A$5:$A$88=J13)*('Datos - GPS Dias Ago'!$B$5:$B$88=TEXT(B13,"yyyy-mm-dd")))>0,1,0) -> 1 | L13: =IF(AND(COUNTIFS($I$4:I13,I13,$B$4:B13,B13)=1,K13=1),1,0) -> 0
A14: DSDV36 | B14: 2026-08-06 | C14: Nano Presmita | D14: Coltauco | E14: Valparaiso | F14: 450000 | G14: =F14/1.19 -> 378151.26 | H14: Pendiente | I14: Nicolas Vega | J14: =IF(A14="DSDV36","DVDS36",A14) -> DVDS36 | K14: =IF(SUMPRODUCT(('Datos - GPS Dias Ago'!$A$5:$A$88=J14)*('Datos - GPS Dias Ago'!$B$5:$B$88=TEXT(B14,"yyyy-mm-dd")))>0,1,0) -> 1 | L14: =IF(AND(COUNTIFS($I$4:I14,I14,$B$4:B14,B14)=1,K14=1),1,0) -> 1
A15: GKFD84 | B15: 2026-08-07 | C15: Sollem | D15: Casa Blanca | E15: San Fernando | F15: 654162.04 | G15: =F15/1.19 -> 549716 | H15: Pendiente | I15: Felipe Madariaga | J15: =IF(A15="DSDV36","DVDS36",A15) -> GKFD84 | K15: =IF(SUMPRODUCT(('Datos - GPS Dias Ago'!$A$5:$A$88=J15)*('Datos - GPS Dias Ago'!$B$5:$B$88=TEXT(B15,"yyyy-mm-dd")))>0,1,0) -> 1 | L15: =IF(AND(COUNTIFS($I$4:I15,I15,$B$4:B15,B15)=1,K15=1),1,0) -> 1
... A63: GCFF12 | B63: 2026-08-26 | C63: Sollem | D63: Casa Blanca | E63: Los Andes - San Felipe | F63: 605472 | G63: =F63/1.19 -> 508800 | H63: Pendiente | I63: Francisco Mancilla | J63: =IF(A63="DSDV36","DVDS36",A63) -> GCFF12 | K63: =IF(SUMPRODUCT(('Datos - GPS Dias Ago'!$A$5:$A$88=J63)*('Datos - GPS Dias Ago'!$B$5:$B$88=TEXT(B63,"yyyy-mm-dd")))>0,1,0) -> 1 | L63: =IF(AND(COUNTIFS($I$4:I63,I63,$B$4:B63,B63)=1,K63=1),1,0) -> 1
A64: - | B64: 2026-08-27 | C64: Sollem | D64: Casa Blanca | E64: Chepica - Santa Cruz | F64: 808300.36 | G64: =F64/1.19 -> 679244 | H64: Pendiente | J64: =IF(A64="DSDV36","DVDS36",A64) -> - | K64: =IF(SUMPRODUCT(('Datos - GPS Dias Ago'!$A$5:$A$88=J64)*('Datos - GPS Dias Ago'!$B$5:$B$88=TEXT(B64,"yyyy-mm-dd")))>0,1,0) -> 0 | L64: =IF(AND(COUNTIFS($I$4:I64,I64,$B$4:B64,B64)=1,K64=1),1,0) -> 0
A65: XR8555 | B65: 2026-08-27 | C65: Sollem | D65: Casa Blanca | E65: San Fernando | F65: 654162.04 | G65: =F65/1.19 -> 549716 | H65: Pendiente | I65: Manuel Madrid | J65: =IF(A65="DSDV36","DVDS36",A65) -> XR8555 | K65: =IF(SUMPRODUCT(('Datos - GPS Dias Ago'!$A$5:$A$88=J65)*('Datos - GPS Dias Ago'!$B$5:$B$88=TEXT(B65,"yyyy-mm-dd")))>0,1,0) -> 1 | L65: =IF(AND(COUNTIFS($I$4:I65,I65,$B$4:B65,B65)=1,K65=1),1,0) -> 1
A66: GKFD84 | B66: 2026-08-27 | C66: Sollem | D66: Casa Blanca | E66: San Fernando - Chimbarongo - Santa Cruz - Lolol - Peralillo | F66: 1025669.3 | G66: =F66/1.19 -> 861907 | H66: Pendiente | I66: Felipe Madariaga | J66: =IF(A66="DSDV36","DVDS36",A66) -> GKFD84 | K66: =IF(SUMPRODUCT(('Datos - GPS Dias Ago'!$A$5:$A$88=J66)*('Datos - GPS Dias Ago'!$B$5:$B$88=TEXT(B66,"yyyy-mm-dd")))>0,1,0) -> 1 | L66: =IF(AND(COUNTIFS($I$4:I66,I66,$B$4:B66,B66)=1,K66=1),1,0) -> 0
A67: GCFF12 | B67: 2026-08-27 | C67: Sollem | D67: Casa Blanca | E67: Hijuelas - San Felipe | F67: 747796 | G67: =F67/1.19 -> 628400 | H67: Pendiente | I67: Francisco Mancilla | J67: =IF(A67="DSDV36","DVDS36",A67) -> GCFF12 | K67: =IF(SUMPRODUCT(('Datos - GPS Dias Ago'!$A$5:$A$88=J67)*('Datos - GPS Dias Ago'!$B$5:$B$88=TEXT(B67,"yyyy-mm-dd")))>0,1,0) -> 1 | L67: =IF(AND(COUNTIFS($I$4:I67,I67,$B$4:B67,B67)=1,K67=1),1,0) -> 1
A68: DSDV36 | B68: 2026-08-26 | C68: Don Hugo | D68: Romeral | E68: Coltauco | F68: 270000 | G68: =F68/1.19 -> 226890.76 | H68: Pendiente | I68: Francisco Medina | J68: =IF(A68="DSDV36","DVDS36",A68) -> DVDS36 | K68: =IF(SUMPRODUCT(('Datos - GPS Dias Ago'!$A$5:$A$88=J68)*('Datos - GPS Dias Ago'!$B$5:$B$88=TEXT(B68,"yyyy-mm-dd")))>0,1,0) -> 1 | L68: =IF(AND(COUNTIFS($I$4:I68,I68,$B$4:B68,B68)=1,K68=1),1,0) -> 1
A69: DSDV36 | B69: 2026-08-27 | C69: Don Hugo | D69: Romeral | E69: Coltauco | F69: 270000 | G69: =F69/1.19 -> 226890.76 | H69: Pendiente | I69: Francisco Medina | J69: =IF(A69="DSDV36","DVDS36",A69) -> DVDS36 | K69: =IF(SUMPRODUCT(('Datos - GPS Dias Ago'!$A$5:$A$88=J69)*('Datos - GPS Dias Ago'!$B$5:$B$88=TEXT(B69,"yyyy-mm-dd")))>0,1,0) -> 1 | L69: =IF(AND(COUNTIFS($I$4:I69,I69,$B$4:B69,B69)=1,K69=1),1,0) -> 1
A70: DSDV36 | B70: 2026-08-27 | C70: Nano Presmita | D70: Coltauco | E70: Valparaiso | F70: 450000 | G70: =F70/1.19 -> 378151.26 | H70: Pendiente | I70: Francisco Medina | J70: =IF(A70="DSDV36","DVDS36",A70) -> DVDS36 | K70: =IF(SUMPRODUCT(('Datos - GPS Dias Ago'!$A$5:$A$88=J70)*('Datos - GPS Dias Ago'!$B$5:$B$88=TEXT(B70,"yyyy-mm-dd")))>0,1,0) -> 1 | L70: =IF(AND(COUNTIFS($I$4:I70,I70,$B$4:B70,B70)=1,K70=1),1,0) -> 0
A71: GCFF12 | B71: 2026-08-28 | C71: Sollem | D71: Casa Blanca | E71: San Fernando | F71: 654162.04 | G71: =F71/1.19 -> 549716 | H71: Pendiente | I71: Francisco Mancilla | J71: =IF(A71="DSDV36","DVDS36",A71) -> GCFF12 | K71: =IF(SUMPRODUCT(('Datos - GPS Dias Ago'!$A$5:$A$88=J71)*('Datos - GPS Dias Ago'!$B$5:$B$88=TEXT(B71,"yyyy-mm-dd")))>0,1,0) -> 1 | L71: =IF(AND(COUNTIFS($I$4:I71,I71,$B$4:B71,B71)=1,K71=1),1,0) -> 1
A72: DSDV36 | B72: 2026-08-31 | C72: Nano Presmita | D72: Coltauco | E72: Valparaiso | F72: 450000 | G72: =F72/1.19 -> 378151.26 | H72: Pagado | I72: Francisco Mancilla | J72: =IF(A72="DSDV36","DVDS36",A72) -> DVDS36 | K72: =IF(SUMPRODUCT(('Datos - GPS Dias Ago'!$A$5:$A$88=J72)*('Datos - GPS Dias Ago'!$B$5:$B$88=TEXT(B72,"yyyy-mm-dd")))>0,1,0) -> 1 | L72: =IF(AND(COUNTIFS($I$4:I72,I72,$B$4:B72,B72)=1,K72=1),1,0) -> 1
A73: GKFD84 | B73: 2026-08-31 | C73: Sollem | D73: Casa Blanca | E73: Coltauco - Requinoa - Quinta Tilcoco | F73: 715944.46 | G73: =F73/1.19 -> 601634 | H73: Pendiente | I73: Felipe Madariaga | J73: =IF(A73="DSDV36","DVDS36",A73) -> GKFD84 | K73: =IF(SUMPRODUCT(('Datos - GPS Dias Ago'!$A$5:$A$88=J73)*('Datos - GPS Dias Ago'!$B$5:$B$88=TEXT(B73,"yyyy-mm-dd")))>0,1,0) -> 1 | L73: =IF(AND(COUNTIFS($I$4:I73,I73,$B$4:B73,B73)=1,K73=1),1,0) -> 1
A74: XR8555 | B74: 2026-08-31 | C74: Sollem | D74: Casa Blanca | E74: San Fernando | F74: 724157.38 | G74: =F74/1.19 -> 608535.61 | H74: Pendiente | I74: Manuel Madrid | J74: =IF(A74="DSDV36","DVDS36",A74) -> XR8555 | K74: =IF(SUMPRODUCT(('Datos - GPS Dias Ago'!$A$5:$A$88=J74)*('Datos - GPS Dias Ago'!$B$5:$B$88=TEXT(B74,"yyyy-mm-dd")))>0,1,0) -> 1 | L74: =IF(AND(COUNTIFS($I$4:I74,I74,$B$4:B74,B74)=1,K74=1),1,0) -> 1
A75: - | B75: 2026-08-31 | C75: Sollem | D75: Casa Blanca | E75: Maria Pinto | F75: 396697.94 | G75: =F75/1.19 -> 333359.61 | H75: Pendiente | I75: Alex Espinoza | J75: =IF(A75="DSDV36","DVDS36",A75) -> - | K75: =IF(SUMPRODUCT(('Datos - GPS Dias Ago'!$A$5:$A$88=J75)*('Datos - GPS Dias Ago'!$B$5:$B$88=TEXT(B75,"yyyy-mm-dd")))>0,1,0) -> 0 | L75: =IF(AND(COUNTIFS($I$4:I75,I75,$B$4:B75,B75)=1,K75=1),1,0) -> 0
E76: TOTAL | F76: =SUM(F4:F75) -> 35464462 | G76: =SUM(G4:G75) -> 29802069

Sheet Datos - Cartola Ago
A1: CARTOLA BANCARIA REAL — AGOSTO 2026
A3: Fecha | B3: Tipo | C3: Categoria | D3: Monto | E3: Referencia | F3: Patente (si aplica) | G3: Concepto real (si es otro_por_clasificar)
A4: 2026-08-03 | B4: egreso | C4: combustible | D4: 1400000 | E4: PAGO EN LINEA ESMAX
A5: 2026-08-03 | B5: egreso | C5: sueldo_coordinador | D5: 1000000 | E5: 0159957802 Transf a RIQUELME OLEA
A6: 2026-08-03 | B6: egreso | C6: otro_por_clasificar | D6: 300000 | E6: 0168844255 Transf a Sebastián Zúñi
A7: 2026-08-03 | B7: egreso | C7: sueldo_coordinador | D7: 130000 | E7: 0159957802 Transf a RIQUELME OLEA
A8: 2026-08-03 | B8: egreso | C8: sueldo_conductor | D8: 115000 | E8: 0153706123 Transf a Francisco Manc
A9: 2026-08-03 | B9: egreso | C9: sueldo_conductor | D9: 100000 | E9: 0153706123 Transf a Francisco Manc
A10: 2026-08-03 | B10: egreso | C10: otro_por_clasificar | D10: 60000 | E10: 019591141K Transf a Nicolás Matías
A11: 2026-08-03 | B11: egreso | C11: sueldo_conductor | D11: 15000 | E11: 0153706123 Transf a Francisco Manc
A12: 2026-08-03 | B12: egreso | C12: otro_por_clasificar | D12: 3200 | E12: 0168844255 Transf a Sebastián Zúñi
A13: 2026-08-04 | B13: ingreso | C13: factoring | D13: 3053216 | E13: 0966265701 Transf. INCOFIN S A
A14: 2026-08-04 | B14: ingreso | C14: factoring | D14: 605464 | E14: 0966265701 Transf. INCOFIN S A
A15: 2026-08-04 | B15: egreso | C15: sueldo_coordinador | D15: 850000 | E15: 0159957802 Transf a RIQUELME OLEA
... A179: 2026-08-31 | B179: egreso | C179: sueldo_conductor | D179: 18000 | E179: 0142013436 Transf a Felipe Madaria

Sheet Datos - Combustible y GPS Ago
A1: COMBUSTIBLE REAL (ARAMCO+COPEC) Y KM GPS POR EQUIPO — AGOSTO 2026
A3: Patente | B3: Tipo equipo | C3: Litros (Aramco+Copec) | D3: Monto $ | E3: Km recorridos (GPS, trip)
A4: DVDS36 | B4: Camión | C4: 1150.1 | D4: 1409841 | E4: 4373.267
A5: GCFF12 | B5: Camión | C5: 3031.3 | D5: 3736980 | E5: 5299.228
A6: GKFD84 | B6: Camión | C6: 2987 | D6: 3663449 | E6: 6568.06
A7: KSRC78 | B7: Camioneta | C7: 714.8 | D7: 907953 | E7: SIN GPS
A8: WR9192 | B8: Camión | C8: 1558.6 | D8: 1973411 | E8: 112.527
A9: XR8555 | B9: Camión | C9: 523.1 | D9: 623347 | E9: 5338.884
A10: JYJV21 | B10: Camioneta | C10: 77.4 | D10: 98134 | E10: SIN GPS

Sheet Datos - GPS Dias Ago
A1: DIAS REALES CON MOVIMIENTO GPS — AGOSTO 2026
A3: Patente | B3: Fecha
A4: DVDS36 | B4: 2026-08-03
A5: DVDS36 | B5: 2026-08-06
A6: DVDS36 | B6: 2026-08-07
A7: DVDS36 | B7: 2026-08-10
A8: DVDS36 | B8: 2026-08-11
A9: DVDS36 | B9: 2026-08-13
A10: DVDS36 | B10: 2026-08-14
A11: DVDS36 | B11: 2026-08-17
A12: DVDS36 | B12: 2026-08-18
A13: DVDS36 | B13: 2026-08-20
A14: DVDS36 | B14: 2026-08-21
... A88: XR8555 | B88: 2026-08-31
