Workbook

Sheet Presupuesto
A1: PRESUPUESTO — PARAMETROS FIJOS (editar aqui, se usan en todo el informe)
A2: Cambia un valor aca y se recalcula en Financiero y Operacional automaticamente. No hay numeros sueltos en otras hojas.
A4: Parametro | B4: Valor | C4: Nota
A5: SueldoConductorMes | B5: 660000 | C5: Sueldo fijo mensual bruto por conductor, con contrato desde agosto
A6: ComisionConductorPct | B6: 0.08 | C6: % sobre ventas netas del conductor
A7: ViaticoDia | B7: 12000 | C7: Por dia confirmado con GPS real
A8: CoordinadorOperaciones | B8: 1500000 | C8: Pablo Riquelme, valor fijo
A9: AyudanteOperaciones | B9: 900000 | C9: Sebastian Zuniga, valor fijo
A10: AdministrativoControlGestion | B10: 500000 | C10: Carlos Torres, valor fijo
A11: Arriendo | B11: 450000
A12: Contabilidad | B12: 50000
A13: GastosComunes | B13: 100000
A14: Permisos | B14: 0
A15: ProvisionFiniquitos | B15: 0
A16: UFVigente | B16: 41074 | C16: Editar cada mes
A17: UmbralB_UF | B17: 8000 | C17: Tramo devolucion imp. especifico diesel, confirmar con contador
A18: UmbralC_UF | B18: 20000 | C18: Tramo devolucion imp. especifico diesel
A19: ImpEspecificoPorLitro | B19: 102 | C19: Componente base, $/lt
A20: DiasHabilesMes | B20: 23 | C20: Editar cada mes
A21: FactorIVA | B21: 1.19
I97: =(Presupuesto!$B$8+Presupuesto!$B$9+Presupuesto!$B$10+Presupuesto!$B$11+Presupuesto!$B$12+Presupuesto!$B$13+Presupuesto!$B$14+Presupuesto!$B$15)/5 -> 700000
I98: =(Presupuesto!$B$8+Presupuesto!$B$9+Presupuesto!$B$10+Presupuesto!$B$11+Presupuesto!$B$12+Presupuesto!$B$13+Presupuesto!$B$14+Presupuesto!$B$15)/5 -> 700000
I99: =(Presupuesto!$B$8+Presupuesto!$B$9+Presupuesto!$B$10+Presupuesto!$B$11+Presupuesto!$B$12+Presupuesto!$B$13+Presupuesto!$B$14+Presupuesto!$B$15)/5 -> 700000
I100: =(Presupuesto!$B$8+Presupuesto!$B$9+Presupuesto!$B$10+Presupuesto!$B$11+Presupuesto!$B$12+Presupuesto!$B$13+Presupuesto!$B$14+Presupuesto!$B$15)/5 -> 700000
I101: =(Presupuesto!$B$8+Presupuesto!$B$9+Presupuesto!$B$10+Presupuesto!$B$11+Presupuesto!$B$12+Presupuesto!$B$13+Presupuesto!$B$14+Presupuesto!$B$15)/5 -> 700000
I102: =(Presupuesto!$B$8+Presupuesto!$B$9+Presupuesto!$B$10+Presupuesto!$B$11+Presupuesto!$B$12+Presupuesto!$B$13+Presupuesto!$B$14+Presupuesto!$B$15)/5 -> 700000

Sheet Financiero
A1: INFORME EJECUTIVO — AMBITO FINANCIERO — JULIO 2026
A2: Formulas vivas. Usa los botones +/- (arriba a la izquierda) para expandir cada item y ver su desglose real.
A4: Concepto | B4: Monto
A5: RENTABILIDAD
A6: Ventas netas reales | B6: ='Datos - Servicios Jul'!G45 -> 16728894
A7: Ventas por equipo:
A8: DVDS36 | B8: =SUMIFS('Datos - Servicios Jul'!$G$4:$G$44,'Datos - Servicios Jul'!$J$4:$J$44,"DVDS36") -> 2766807.2
A9: GCFF12 | B9: =SUMIFS('Datos - Servicios Jul'!$G$4:$G$44,'Datos - Servicios Jul'!$J$4:$J$44,"GCFF12") -> 4349600
A10: GKFD84 | B10: =SUMIFS('Datos - Servicios Jul'!$G$4:$G$44,'Datos - Servicios Jul'!$J$4:$J$44,"GKFD84") -> 7313185.7
A11: WR9192 | B11: =SUMIFS('Datos - Servicios Jul'!$G$4:$G$44,'Datos - Servicios Jul'!$J$4:$J$44,"WR9192") -> 747200
A12: XR8555 | B12: =SUMIFS('Datos - Servicios Jul'!$G$4:$G$44,'Datos - Servicios Jul'!$J$4:$J$44,"XR8555") -> 1552100.8
A13: BPLB35 | B13: =SUMIFS('Datos - Servicios Jul'!$G$4:$G$44,'Datos - Servicios Jul'!$J$4:$J$44,"BPLB35") -> 0
A15: Costos de operacion | B15: =B16+B29+B50+B57 -> 11743479
A16: 1. Combustible y costos de ruta | B16: =B18-B27+B28 -> 6087990.5
A17: Combustible bruto (con IVA, Aramco) | B17: =SUMIFS('Datos - Cartola Jul'!$D$5:$D$167,'Datos - Cartola Jul'!$C$5:$C$167,"combustible",'Datos - Cartola Jul'!$B$5:$B$167,"egreso") -> 6159145
A18: Combustible neto IVA (÷1,19) | B18: =B17/Presupuesto!$B$21 -> 5175752.1
A19: Venta anual proyectada (mes x 12) | B19: =B6*12 -> 2.0074673e+08
A20: UF vigente (editar c/mes) | B20: =Presupuesto!$B$16 -> 41074
A21: Venta anual proyectada en UF | B21: =B19/B20 -> 4887.4404
A22: Umbral B UF/año (editar segun SII, hoy <=70%) | B22: =Presupuesto!$B$17 -> 8000
A23: Umbral C UF/año (editar segun SII, hoy <=52,5%) | B23: =Presupuesto!$B$18 -> 20000
A24: % Devolucion imp. especifico (dinamico segun tramo) | B24: =IF(B21<=2400,0.8,IF(B21<=B22,0.7,IF(B21<=B23,0.525,0.31))) -> 0.7
A25: Componente base imp. especifico ($/lt, editar) | B25: =Presupuesto!$B$19 -> 102
A26: Litros julio (camiones+camioneta) | B26: =SUM('Datos - Combustible y GPS'!C4:B18) -> 6349.7
A27: Devolucion impuesto especifico diesel | B27: =B26*B25*B24 -> 453368.58
A28: Peajes (real concesionarias GKFD84+KSRC78 + reembolso resto flota) | B28: =932332+123275+SUMIFS('Datos - Cartola Jul'!$D$5:$D$167,'Datos - Cartola Jul'!$C$5:$C$167,"peajes",'Datos - Cartola Jul'!$B$5:$B$167,"egreso") -> 1365607
A29: 2. Remuneraciones | B29: =B30+B34+B38+B42+B46 -> 4428311.5
A30: 2.1 Felipe Madariaga (conductor) | B30: =B31+B32+B33 -> 1460244.9
A31: Sueldo | B31: =Presupuesto!$B$5 -> 660000
A32: Comision 8% sobre sus ventas netas | B32: =SUMIFS('Datos - Servicios Jul'!$G$4:$G$44,'Datos - Servicios Jul'!$I$4:$I$44,"*Madariaga*")*Presupuesto!$B$6 -> 632244.92
A33: Viatico ($12.000 x dias con servicio) | B33: =Presupuesto!$B$7*SUMIFS('Datos - Servicios Jul'!$L$4:$L$44,'Datos - Servicios Jul'!$I$4:$I$44,"*Madariaga*") -> 168000
A34: 2.2 Francisco Mancilla (conductor) | B34: =B35+B36+B37 -> 1125280
A35: Sueldo | B35: =Presupuesto!$B$5 -> 660000
A36: Comision 8% sobre sus ventas netas | B36: =SUMIFS('Datos - Servicios Jul'!$G$4:$G$44,'Datos - Servicios Jul'!$I$4:$I$44,"*Mancilla*")*Presupuesto!$B$6 -> 381280
A37: Viatico ($12.000 x dias con servicio) | B37: =Presupuesto!$B$7*SUMIFS('Datos - Servicios Jul'!$L$4:$L$44,'Datos - Servicios Jul'!$I$4:$I$44,"*Mancilla*") -> 84000
A38: 2.3 Manuel Madrid (conductor) | B38: =B39+B40+B41 -> 1035072.3
A39: Sueldo | B39: =Presupuesto!$B$5 -> 660000
A40: Comision 8% sobre sus ventas netas | B40: =SUMIFS('Datos - Servicios Jul'!$G$4:$G$44,'Datos - Servicios Jul'!$I$4:$I$44,"*Madrid*")*Presupuesto!$B$6 -> 267072.27
A41: Viatico ($12.000 x dias con servicio) | B41: =Presupuesto!$B$7*SUMIFS('Datos - Servicios Jul'!$L$4:$L$44,'Datos - Servicios Jul'!$I$4:$I$44,"*Madrid*") -> 108000
A42: 2.4 Felipe Vidal (conductor) | B42: =B43+B44+B45 -> 660000
...

Sheet Comercial
A1: INFORME EJECUTIVO — AMBITO COMERCIAL — JULIO 2026
A2: Fuente: hoja de servicios de Pablo (julio) + historico real de servicios_piloto (Supabase) para Fidelizacion.
A4: PILAR 1 — DISTRIBUCION / CONCENTRACION DE CARTERA (reemplaza participacion de mercado)
A5: Cliente | B5: Ventas julio | C5: % de la cartera
A6: Sollem | B6: 9949471 | C6: =B6/$B$13 -> 0.49978799
A7: Nano Presmita | B7: 3869500 | C7: =B7/$B$13 -> 0.19437512
A8: Serlogin | B8: 3099712 | C8: =B8/$B$13 -> 0.15570665
A9: Trans Luciano | B9: 1249500 | C9: =B9/$B$13 -> 0.062765658
A10: Andrea Alacon | B10: 1240200 | C10: =B10/$B$13 -> 0.062298495
A11: Rata | B11: 380000 | C11: =B11/$B$13 -> 0.019088395
A12: Victor Frutillero | B12: 119000 | C12: =B12/$B$13 -> 0.0059776817
A13: TOTAL | B13: =SUM(B6:B12) -> 19907383
A17: PILAR 2 — FIDELIZACION (sin contratos firmados)
A18: Cliente | B18: Antiguedad (desde) | C18: Meses con actividad | D18: Consistencia | E18: Valor de vida acumulado
A23: Clientes con 1 solo mes de actividad (recien incorporados, aun sin antiguedad real): Danilo Nunez, Serlogin, Agricola Don Hugo, TRAST Logistics, Kapital Box, Rucaray.
A25: PILAR 3 — DIVERSIFICACION
A26: Clientes activos en julio
A27: Clientes nuevos incorporados en julio (vs. meses previos)
A28: % dependencia del cliente principal (Sollem)

Sheet Operacional
A1: INFORME EJECUTIVO — AMBITO OPERACIONAL — JULIO 2026
A2: Formulas vivas. Mantencion por equipo requiere que completes la columna Patente en Datos-Cartola Jul.
A4: COMBUSTIBLE — camiones + camionetas (Aramco+Copec)
A5: Patente | B5: Tipo | C5: Litros | D5: Monto $ | E5: % del total
A6: ='Datos - Combustible y GPS'!A4 -> DVDS36 | B6: ='Datos - Combustible y GPS'!B4 -> Camión | C6: ='Datos - Combustible y GPS'!C4 -> 1011 | D6: ='Datos - Combustible y GPS'!D4 -> 1202490 | E6: =D6/SUM('Datos - Combustible y GPS'!D4:D10) -> 0.15893916
A7: ='Datos - Combustible y GPS'!A5 -> GCFF12 | B7: ='Datos - Combustible y GPS'!B5 -> Camión | C7: ='Datos - Combustible y GPS'!C5 -> 1235.6 | D7: ='Datos - Combustible y GPS'!D5 -> 1467626 | E7: =D7/SUM('Datos - Combustible y GPS'!D4:D10) -> 0.19398352
A8: ='Datos - Combustible y GPS'!A6 -> GKFD84 | B8: ='Datos - Combustible y GPS'!B6 -> Camión | C8: ='Datos - Combustible y GPS'!C6 -> 2605.4 | D8: ='Datos - Combustible y GPS'!D6 -> 3114070 | E8: =D8/SUM('Datos - Combustible y GPS'!D4:D10) -> 0.41160232
A9: ='Datos - Combustible y GPS'!A7 -> KSRC78 | B9: ='Datos - Combustible y GPS'!B7 -> Camioneta | C9: ='Datos - Combustible y GPS'!C7 -> 456.8 | D9: ='Datos - Combustible y GPS'!D7 -> 565507 | E9: =D9/SUM('Datos - Combustible y GPS'!D4:D10) -> 0.07474591
A10: ='Datos - Combustible y GPS'!A8 -> WR9192 | B10: ='Datos - Combustible y GPS'!B8 -> Camión | C10: ='Datos - Combustible y GPS'!C8 -> 369.9 | D10: ='Datos - Combustible y GPS'!D8 -> 431517 | E10: =D10/SUM('Datos - Combustible y GPS'!D4:D10) -> 0.057035776
A11: ='Datos - Combustible y GPS'!A9 -> XR8555 | B11: ='Datos - Combustible y GPS'!B9 -> Camión | C11: ='Datos - Combustible y GPS'!C9 -> 629.9 | D11: ='Datos - Combustible y GPS'!D9 -> 734515 | E11: =D11/SUM('Datos - Combustible y GPS'!D4:D10) -> 0.097084549
A12: ='Datos - Combustible y GPS'!A10 -> JYJV21 | B12: ='Datos - Combustible y GPS'!B10 -> Camioneta | C12: ='Datos - Combustible y GPS'!C10 -> 41.1 | D12: ='Datos - Combustible y GPS'!D10 -> 50000 | E12: =D12/SUM('Datos - Combustible y GPS'!D4:D10) -> 0.006608752
A14: RENDIMIENTO km/lt — SOLO CAMIONES (excluye camionetas KSRC78, JYJV21)
A15: Patente | B15: Litros | C15: Km GPS | D15: Rendimiento (km/lt)
A16: =IF('Datos - Combustible y GPS'!B4="Camión",'Datos - Combustible y GPS'!A4,"") -> DVDS36 | B16: =IF('Datos - Combustible y GPS'!B4="Camión",'Datos - Combustible y GPS'!C4,"") -> 1011 | C16: =IF(AND('Datos - Combustible y GPS'!B4="Camión",ISNUMBER('Datos - Combustible y GPS'!E4)),'Datos - Combustible y GPS'!E4,"") -> 3682.959 | D16: =IFERROR(C16/B16,"") -> 3.6428872
A17: =IF('Datos - Combustible y GPS'!B5="Camión",'Datos - Combustible y GPS'!A5,"") -> GCFF12 | B17: =IF('Datos - Combustible y GPS'!B5="Camión",'Datos - Combustible y GPS'!C5,"") -> 1235.6 | C17: =IF(AND('Datos - Combustible y GPS'!B5="Camión",ISNUMBER('Datos - Combustible y GPS'!E5)),'Datos - Combustible y GPS'!E5,"") -> 2450.405 | D17: =IFERROR(C17/B17,"") -> 1.9831701
A18: =IF('Datos - Combustible y GPS'!B6="Camión",'Datos - Combustible y GPS'!A6,"") -> GKFD84 | B18: =IF('Datos - Combustible y GPS'!B6="Camión",'Datos - Combustible y GPS'!C6,"") -> 2605.4 | C18: =IF(AND('Datos - Combustible y GPS'!B6="Camión",ISNUMBER('Datos - Combustible y GPS'!E6)),'Datos - Combustible y GPS'!E6,"") -> 5277.71 | D18: =IFERROR(C18/B18,"") -> 2.0256813
A19: =IF('Datos - Combustible y GPS'!B8="Camión",'Datos - Combustible y GPS'!A8,"") -> WR9192 | B19: =IF('Datos - Combustible y GPS'!B8="Camión",'Datos - Combustible y GPS'!C8,"") -> 369.9 | C19: =IF(AND('Datos - Combustible y GPS'!B8="Camión",ISNUMBER('Datos - Combustible y GPS'!E8)),'Datos - Combustible y GPS'!E8,"") -> 933.913 | D19: =IFERROR(C19/B19,"") -> 2.5247716
A20: =IF('Datos - Combustible y GPS'!B9="Camión",'Datos - Combustible y GPS'!A9,"") -> XR8555 | B20: =IF('Datos - Combustible y GPS'!B9="Camión",'Datos - Combustible y GPS'!C9,"") -> 629.9 | C20: =IF(AND('Datos - Combustible y GPS'!B9="Camión",ISNUMBER('Datos - Combustible y GPS'!E9)),'Datos - Combustible y GPS'!E9,"") -> 1403.627 | D20: =IFERROR(C20/B20,"") -> 2.2283331
A22: =IF('Datos - Combustible y GPS'!B10="Camión",'Datos - Combustible y GPS'!A10,"") | B22: =IF('Datos - Combustible y GPS'!B10="Camión",'Datos - Combustible y GPS'!C10,"") | C22: =IF(AND('Datos - Combustible y GPS'!B10="Camión",ISNUMBER('Datos - Combustible y GPS'!E10)),'Datos - Combustible y GPS'!E10,"") | D22: =IFERROR(C22/B22,"")
A24: MANTENCION — SOLO CAMIONES, desglose por equipo (neto IVA)
A25: Completa la columna Patente en Datos-Cartola Jul para que esto se llene solo.
A26: Patente (camión) | B26: Mantencion neta IVA
A27: DVDS36 | B27: =SUMIFS('Datos - Cartola Jul'!$D$5:$D$167,'Datos - Cartola Jul'!$C$5:$C$167,"mantencion",'Datos - Cartola Jul'!$B$5:$B$167,"egreso",'Datos - Cartola Jul'!$F$5:$F$167,A27)/Presupuesto!$B$21 -> 0
A28: GCFF12 | B28: =SUMIFS('Datos - Cartola Jul'!$D$5:$D$167,'Datos - Cartola Jul'!$C$5:$C$167,"mantencion",'Datos - Cartola Jul'!$B$5:$B$167,"egreso",'Datos - Cartola Jul'!$F$5:$F$167,A28)/Presupuesto!$B$21 -> 0
A29: GKFD84 | B29: =SUMIFS('Datos - Cartola Jul'!$D$5:$D$167,'Datos - Cartola Jul'!$C$5:$C$167,"mantencion",'Datos - Cartola Jul'!$B$5:$B$167,"egreso",'Datos - Cartola Jul'!$F$5:$F$167,A29)/Presupuesto!$B$21 -> 0
A30: WR9192 | B30: =SUMIFS('Datos - Cartola Jul'!$D$5:$D$167,'Datos - Cartola Jul'!$C$5:$C$167,"mantencion",'Datos - Cartola Jul'!$B$5:$B$167,"egreso",'Datos - Cartola Jul'!$F$5:$F$167,A30)/Presupuesto!$B$21 -> 0
A31: XR8555 | B31: =SUMIFS('Datos - Cartola Jul'!$D$5:$D$167,'Datos - Cartola Jul'!$C$5:$C$167,"mantencion",'Datos - Cartola Jul'!$B$5:$B$167,"egreso",'Datos - Cartola Jul'!$F$5:$F$167,A31)/Presupuesto!$B$21 -> 0
A32: TOTAL mantencion camiones | B32: =B27+B28+B29+B30+B31 -> 0
A33: Mantencion $/km (flota camiones) -- solo referencia, NO se usa en el informe de resultados | B33: =B32/SUMIFS('Datos - Combustible y GPS'!E4:E10,'Datos - Combustible y GPS'!B4:B10,"Camión") -> 0
A35: OCUPACION POR EQUIPO — fuente: GPS real (dias con trip)
A36: Dias habiles del mes (editar c/mes) | B36: =Presupuesto!$B$20 -> 23
A37: Patente | B37: Dias con GPS real (trip) | C37: % Ocupacion (sobre dias habiles)
A38: DVDS36 | B38: =COUNTIF('Datos - GPS Dias'!$A$5:$A$70,A38) -> 17 | C38: =B38/$B$36 -> 0.73913043
A39: GCFF12 | B39: =COUNTIF('Datos - GPS Dias'!$A$5:$A$70,A39) -> 10 | C39: =B39/$B$36 -> 0.43478261
A40: GKFD84 | B40: =COUNTIF('Datos - GPS Dias'!$A$5:$A$70,A40) -> 18 | C40: =B40/$B$36 -> 0.7826087
A41: WR9192 | B41: =COUNTIF('Datos - GPS Dias'!$A$5:$A$70,A41) -> 11 | C41: =B41/$B$36 -> 0.47826087
A42: XR8555 | B42: =COUNTIF('Datos - GPS Dias'!$A$5:$A$70,A42) -> 9 | C42: =B42/$B$36 -> 0.39130435
A43: BPLB35 | B43: 0 | C43: =B43/$B$36 -> 0
A45: CALIDAD: sin fuente de datos disponible -- pendiente definir indicador y origen.

Sheet Datos - Servicios Jul
A1: SERVICIOS REALIZADOS — JULIO 2026 (fuente: planilla de control de Pablo)
A3: Patente | B3: Fecha (Fecha GD real) | C3: Cliente | D3: Origen | E3: Destino | F3: Flete Total (bruto) | G3: Flete Neto (=Bruto/1.19) | H3: Estado Pago | I3: Conductor | J3: Patente normalizada | K3: GPS confirma ese dia | L3: Dia unico conf. GPS x conductor
A4: DSDV36 | B4: 2026-07-02 | C4: Nano Presmita | D4: Coltauco | E4: Valparaiso | F4: 479999.59 | G4: =F4/1.19 -> 403361 | H4: Pendiente | I4: Felipe Madariaga | J4: =IF(A4="DSDV36","DVDS36",A4) -> DVDS36 | K4: =IF(SUMPRODUCT(('Datos - GPS Dias'!$A$5:$A$70=J4)*('Datos - GPS Dias'!$B$5:$B$70=TEXT(B4,"yyyy-mm-dd")))>0,1,0) -> 1 | L4: =IF(AND(COUNTIFS($I$4:I4,I4,$B$4:B4,B4)=1,K4=1),1,0) -> 1
A5: DSDV36 | B5: 2026-07-02 | C5: Nano Presmita | D5: Molino | E5: Coltauco | F5: 40000.66 | G5: =F5/1.19 -> 33614 | H5: Pendiente | I5: Felipe Madariaga | J5: =IF(A5="DSDV36","DVDS36",A5) -> DVDS36 | K5: =IF(SUMPRODUCT(('Datos - GPS Dias'!$A$5:$A$70=J5)*('Datos - GPS Dias'!$B$5:$B$70=TEXT(B5,"yyyy-mm-dd")))>0,1,0) -> 1 | L5: =IF(AND(COUNTIFS($I$4:I5,I5,$B$4:B5,B5)=1,K5=1),1,0) -> 0
A6: DSDV36 | B6: 2026-07-02 | C6: Rata | D6: Peumo | E6: Talca | F6: 380000.32 | G6: =F6/1.19 -> 319328 | H6: Pagado | I6: Nicolas Vega | J6: =IF(A6="DSDV36","DVDS36",A6) -> DVDS36 | K6: =IF(SUMPRODUCT(('Datos - GPS Dias'!$A$5:$A$70=J6)*('Datos - GPS Dias'!$B$5:$B$70=TEXT(B6,"yyyy-mm-dd")))>0,1,0) -> 1 | L6: =IF(AND(COUNTIFS($I$4:I6,I6,$B$4:B6,B6)=1,K6=1),1,0) -> 1
A7: GKFD84 | B7: 2026-07-02 | C7: Sollem | D7: Casa Blanca | E7: Placilla - Chepica | F7: 808248 | G7: =F7/1.19 -> 679200 | H7: Pendiente | I7: Felipe Madariaga | J7: =IF(A7="DSDV36","DVDS36",A7) -> GKFD84 | K7: =IF(SUMPRODUCT(('Datos - GPS Dias'!$A$5:$A$70=J7)*('Datos - GPS Dias'!$B$5:$B$70=TEXT(B7,"yyyy-mm-dd")))>0,1,0) -> 0 | L7: =IF(AND(COUNTIFS($I$4:I7,I7,$B$4:B7,B7)=1,K7=1),1,0) -> 0
A8: GKFD84 | B8: 2026-07-06 | C8: Sollem | D8: Placilla | E8: Casa Blanca | F8: 746368 | G8: =F8/1.19 -> 627200 | H8: Pendiente | I8: Felipe Madariaga | J8: =IF(A8="DSDV36","DVDS36",A8) -> GKFD84 | K8: =IF(SUMPRODUCT(('Datos - GPS Dias'!$A$5:$A$70=J8)*('Datos - GPS Dias'!$B$5:$B$70=TEXT(B8,"yyyy-mm-dd")))>0,1,0) -> 1 | L8: =IF(AND(COUNTIFS($I$4:I8,I8,$B$4:B8,B8)=1,K8=1),1,0) -> 1
A9: DSDV36 | B9: 2026-07-06 | C9: Nano Presmita | D9: Coltauco | E9: Valparaiso | F9: 478500 | G9: =F9/1.19 -> 402100.84 | H9: Pendiente | I9: Manuel Madrid | J9: =IF(A9="DSDV36","DVDS36",A9) -> DVDS36 | K9: =IF(SUMPRODUCT(('Datos - GPS Dias'!$A$5:$A$70=J9)*('Datos - GPS Dias'!$B$5:$B$70=TEXT(B9,"yyyy-mm-dd")))>0,1,0) -> 1 | L9: =IF(AND(COUNTIFS($I$4:I9,I9,$B$4:B9,B9)=1,K9=1),1,0) -> 1
A10: GKFD84 | B10: 2026-07-07 | C10: Sollem | D10: Casa Blanca | E10: Peumo | F10: 609280 | G10: =F10/1.19 -> 512000 | H10: Pendiente | I10: Felipe Madariaga | J10: =IF(A10="DSDV36","DVDS36",A10) -> GKFD84 | K10: =IF(SUMPRODUCT(('Datos - GPS Dias'!$A$5:$A$70=J10)*('Datos - GPS Dias'!$B$5:$B$70=TEXT(B10,"yyyy-mm-dd")))>0,1,0) -> 1 | L10: =IF(AND(COUNTIFS($I$4:I10,I10,$B$4:B10,B10)=1,K10=1),1,0) -> 1
A11: DSDV36 | B11: 2026-07-09 | C11: Nano Presmita | D11: Coltauco | E11: Valparaiso | F11: 478500 | G11: =F11/1.19 -> 402100.84 | H11: Pendiente | I11: Felipe Madariaga | J11: =IF(A11="DSDV36","DVDS36",A11) -> DVDS36 | K11: =IF(SUMPRODUCT(('Datos - GPS Dias'!$A$5:$A$70=J11)*('Datos - GPS Dias'!$B$5:$B$70=TEXT(B11,"yyyy-mm-dd")))>0,1,0) -> 1 | L11: =IF(AND(COUNTIFS($I$4:I11,I11,$B$4:B11,B11)=1,K11=1),1,0) -> 1
A12: DSDV36 | B12: 2026-07-12 | C12: Nano Presmita | D12: Coltauco | E12: Valparaiso | F12: 478500 | G12: =F12/1.19 -> 402100.84 | H12: Pendiente | I12: Manuel Madrid | J12: =IF(A12="DSDV36","DVDS36",A12) -> DVDS36 | K12: =IF(SUMPRODUCT(('Datos - GPS Dias'!$A$5:$A$70=J12)*('Datos - GPS Dias'!$B$5:$B$70=TEXT(B12,"yyyy-mm-dd")))>0,1,0) -> 0 | L12: =IF(AND(COUNTIFS($I$4:I12,I12,$B$4:B12,B12)=1,K12=1),1,0) -> 0
A13: GKFD84 | B13: 2026-07-13 | C13: Sollem | D13: Casa Blanca | E13: Placilla - Santa Cruz - Marchigue | F13: 889168 | G13: =F13/1.19 -> 747200 | H13: Pagado | I13: Felipe Madariaga | J13: =IF(A13="DSDV36","DVDS36",A13) -> GKFD84 | K13: =IF(SUMPRODUCT(('Datos - GPS Dias'!$A$5:$A$70=J13)*('Datos - GPS Dias'!$B$5:$B$70=TEXT(B13,"yyyy-mm-dd")))>0,1,0) -> 1 | L13: =IF(AND(COUNTIFS($I$4:I13,I13,$B$4:B13,B13)=1,K13=1),1,0) -> 1
A14: WR9192 | B14: 2026-07-14 | C14: Sollem | D14: Casa Blanca | E14: Requinoa - Chimbarongo - San Fernando | F14: 889168 | G14: =F14/1.19 -> 747200 | H14: Pagado | I14: Francisco Mancilla | J14: =IF(A14="DSDV36","DVDS36",A14) -> WR9192 | K14: =IF(SUMPRODUCT(('Datos - GPS Dias'!$A$5:$A$70=J14)*('Datos - GPS Dias'!$B$5:$B$70=TEXT(B14,"yyyy-mm-dd")))>0,1,0) -> 1 | L14: =IF(AND(COUNTIFS($I$4:I14,I14,$B$4:B14,B14)=1,K14=1),1,0) -> 1
A15: GKFD84 | B15: 2026-07-14 | C15: Sollem | D15: Casa Blanca | E15: Requinoa | F15: 609280 | G15: =F15/1.19 -> 512000 | H15: Pagado | I15: Felipe Madariaga | J15: =IF(A15="DSDV36","DVDS36",A15) -> GKFD84 | K15: =IF(SUMPRODUCT(('Datos - GPS Dias'!$A$5:$A$70=J15)*('Datos - GPS Dias'!$B$5:$B$70=TEXT(B15,"yyyy-mm-dd")))>0,1,0) -> 1 | L15: =IF(AND(COUNTIFS($I$4:I15,I15,$B$4:B15,B15)=1,K15=1),1,0) -> 1
... A44: GKFD84 | B44: 2026-07-30 | C44: Andrea Alacon | D44: San Felipe | E44: Coltauco | F44: 550000 | G44: =F44/1.19 -> 462184.87 | H44: Pendiente | I44: Felipe Madariaga | J44: =IF(A44="DSDV36","DVDS36",A44) -> GKFD84 | K44: =IF(SUMPRODUCT(('Datos - GPS Dias'!$A$5:$A$70=J44)*('Datos - GPS Dias'!$B$5:$B$70=TEXT(B44,"yyyy-mm-dd")))>0,1,0) -> 1 | L44: =IF(AND(COUNTIFS($I$4:I44,I44,$B$4:B44,B44)=1,K44=1),1,0) -> 1
E45: TOTAL | F45: =SUM(F4:F44) -> 19907384 | G45: =SUM(G4:G44) -> 16728894

Sheet Datos - Cartola Jul
A1: CARTOLA BANCARIA REAL — JULIO 2026 (Banco Santander)
A2: Columnas F y G son EDITABLES (fondo amarillo): completa la patente (para Mantencion/Combustible) y/o el concepto real cuando la categoria sea "otro_por_clasificar".
A4: Fecha | B4: Tipo | C4: Categoria | D4: Monto | E4: Referencia | F4: Patente (si aplica) | G4: Concepto real (si es otro_por_clasificar)
A5: 2026-07-01 | B5: egreso | C5: viatico | D5: 6000 | E5: Transf a Felipe Vidal
A6: 2026-07-01 | B6: egreso | C6: combustible | D6: 1300000 | E6: PAGO EN LINEA ESMAX
A7: 2026-07-01 | B7: ingreso | C7: factoring | D7: 2326472 | E7: Transf GLOBAL SOLUTIONS SPA
A8: 2026-07-01 | B8: egreso | C8: peajes | D8: 15000 | E8: Transf a Felipe Vidal
A9: 2026-07-01 | B9: egreso | C9: viatico | D9: 12000 | E9: Transf a Felipe Vidal
A10: 2026-07-01 | B10: egreso | C10: aporte_retiro_socio | D10: 70000 | E10: Transf a RIQUELME OLEA PABLO
A11: 2026-07-02 | B11: egreso | C11: otro_por_clasificar | D11: 54000 | E11: Transf a Jose Acevedo
A12: 2026-07-02 | B12: egreso | C12: remuneracion_administrativa | D12: 225000 | E12: Transf a Sebastian Zuniga
A13: 2026-07-02 | B13: egreso | C13: otro_por_clasificar | D13: 2700 | E13: TUU Comercial Escorpio
A14: 2026-07-02 | B14: egreso | C14: otro_por_clasificar | D14: 190000 | E14: Transf a Nicolas Carvallo
A15: 2026-07-02 | B15: egreso | C15: otro_por_clasificar | D15: 30000 | E15: Transf a Servicios integrales FYR
A16: 2026-07-03 | B16: egreso | C16: mantencion | D16: 299606 | E16: COMERCIAL RIHE LTDA
... A167: 2026-07-31 | B167: egreso | C167: sueldo_conductor | D167: 6000 | E167: Transf a Francisco Mancilla

Sheet Datos - Combustible y GPS
A1: COMBUSTIBLE REAL (ARAMCO + COPEC) Y KM GPS POR EQUIPO — JULIO 2026
A3: Patente | B3: Tipo equipo | C3: Litros (Aramco) | D3: Monto $ (Aramco, con IVA) | E3: Km recorridos (GPS, evento=trip)
A4: DVDS36 | B4: Camión | C4: 1011 | D4: 1202490 | E4: 3682.959
A5: GCFF12 | B5: Camión | C5: 1235.6 | D5: 1467626 | E5: 2450.405
A6: GKFD84 | B6: Camión | C6: 2605.4 | D6: 3114070 | E6: 5277.71
A7: KSRC78 | B7: Camioneta | C7: 456.8 | D7: 565507 | E7: SIN GPS EN JULIO
A8: WR9192 | B8: Camión | C8: 369.9 | D8: 431517 | E8: 933.913
A9: XR8555 | B9: Camión | C9: 629.9 | D9: 734515 | E9: 1403.627
A10: JYJV21 | B10: Camioneta | C10: 41.1 | D10: 50000 | E10: SIN GPS EN JULIO
A13: Fuente: Aramco + Copec combinados.

Sheet Datos - GPS Dias
A1: DIAS REALES CON MOVIMIENTO GPS (evento=trip) POR EQUIPO — JULIO 2026
A2: DVDS36 = DSDV36 (mismo equipo, confirmado). Fuente de verdad para Ocupacion y Viatico.
A4: Patente | B4: Fecha
A5: DVDS36 | B5: 2026-07-02
A6: DVDS36 | B6: 2026-07-03
A7: DVDS36 | B7: 2026-07-04
A8: DVDS36 | B8: 2026-07-06
A9: DVDS36 | B9: 2026-07-07
A10: DVDS36 | B10: 2026-07-09
A11: DVDS36 | B11: 2026-07-10
A12: DVDS36 | B12: 2026-07-13
A13: DVDS36 | B13: 2026-07-14
A14: DVDS36 | B14: 2026-07-15
A15: DVDS36 | B15: 2026-07-20
... A70: XR8555 | B70: 2026-07-30
