Workbook

Sheet Supuestos_Presupuesto
A1: SUPUESTOS DEL PRESUPUESTO — SOLLEM + TRAST
A3: GENERAL
A4: Tasa IVA | B4: 0.19
A6: SOLLEM
A7: Servicios por equipo al mes | B7: 13 | C7: 3 servicios/semana × ~4,3 semanas
A8: Días por servicio (base viático/sueldo) | B8: 1.5 | C8: Supuesto original: 1 servicio cada 1,5 días
A9: Km base servicio 1 punto | B9: 359 | C9: Real, estudio de 48 combos reales (control Pablo) 25-07-2026
A10: Km adicional por punto extra | B10: 50 | C10: Real, mediana 40km/promedio 50km, 35 pares GPS limpios de outliers — estudio 25-07-2026
A11: Rendimiento (km/lt) | B11: 2.5
A12: Precio combustible ($/lt, IVA incluido) | B12: 1200
A13: Peajes por servicio (flat, exento IVA) | B13: 50000 | C13: Confirmado por el usuario 25-07-2026 — no varía por día ni km (dato real exacto no disponible)
A14: Mantención ($/km, neto) | B14: 25 | C14: 250.000 ÷ 10.000km
A15: Sueldo conductor ($/día) | B15: 33000
A16: Viático ($/día) | B16: 12000
A17: Comisión conductor (%, sobre tarifa NETA) | B17: 0.08
A18: Factoring (%, sobre tarifa BRUTA) | B18: 0.03 | C18: Confirmado por el usuario 25-07-2026 — reemplaza 3% s/neto (servicios_piloto) y 6,4% (LIQ-001), ambos descartados
A19: Equipos — Agosto | B19: 2
A20: Equipos — Septiembre | B20: 3
A21: Puntos de entrega por servicio (mínimo) | B21: 2 | C21: Confirmado por el usuario 25-07-2026 — todo servicio SIEMPRE tiene al menos 1 punto adicional
A22: Pago por punto adicional desde el 2° (neto) | B22: 60000 | C22: Confirmado por el usuario 25-07-2026
A23: Costo Fijo Equipo Sollem ($/día) | B23: 29167 | C23: Real, evidencia costo_fijo_dia S-58/S-59/S-60 en servicios_piloto — reemplaza estimado de $36.000 prestado de TRAST
A24: Contingencia ($/día) | B24: 25000 | C24: Real, costo_contingencia en servicios_piloto — línea que faltaba en el modelo anterior
A26: TRAST (combo real de referencia: Padre Hurtado→Quilicura→Llay Llay→Talca→Talca)
A27: Ingreso por combo (neto) | B27: 1020776.8 | C27: Simulador_Combos_TRAST_V8.xlsx, combo 001
A28: Combustible por combo (bruto, IVA incluido) | B28: 286000
A29: Mantención por combo (neto) | B29: 19069 | C29: 715km × $26,67/km
A30: Provisión reparaciones por combo | B30: 50000 | C30: $25.000/día × 2 días
A31: Peajes por combo (ida+vuelta, exento IVA) | B31: 142644 | C31: Local+Reposicionamiento+Sur+Retorno
A32: Sueldo conductor por combo | B32: 66000 | C32: $33.000/día × 2 días
A33: Viático por combo | B33: 24000 | C33: $12.000/día × 2 días
A34: Costo fijo equipo por combo | B34: 72000 | C34: $36.000/día × 2 días
A35: Comisión conductor por combo | B35: 81662 | C35: 8% del ingreso del combo
A36: Factoring por combo (%, sobre ingreso bruto) | B36: 0.015 | C36: 1,5% del ingreso
A37: Días por combo | B37: 2
A38: Combos por mes (1 equipo) | B38: 10 | C38: Aún no partimos con este servicio — usar este combo de referencia
A39: Equipos — Agosto | B39: 1
A40: Equipos — Septiembre | B40: 1
A42: COMPARTIDOS / EMPRESA (no atribuibles a un cliente)
A43: Costo Cuenta Corriente Bancaria ($/mes, exento IVA) | B43: 9000
A44: Costo fijo estructural ($/mes, neto) | B44: 3940000 | C44: Coordinador+Mantenedor+Controller+Arriendo+Contabilidad+Gastos comunes+GPS
...

Sheet Sollem
A1: SOLLEM — INGRESO, COSTOS DIRECTOS Y MARGEN (Agosto vs. Septiembre)
A3: Concepto | B3: Agosto | C3: Septiembre
A4: MEMORIA DE CÁLCULO — COMBOS REALES (control Pablo, 79 combos de 127 servicios en Sexta Región ampliada, 25-07-2026)
A5: Muestra de 15 combos más frecuentes = 60 de 127 servicios reales (127 = servicios con destino 100% Sexta Región, de 167 totales). Tarifa Base = "Nueva Tarifa Final" (con baja) del destino de mayor valor de la ruta, tarifario Agosto. Puntos usados = máx(puntos reales, 2) — mínimo 2 puntos siempre. Km = Km base 1 punto + Km adicional × (Puntos usados − 1).
A6: Combo | B6: N obs. | C6: Ptos reales | D6: Ptos usados | E6: Tarifa Base | F6: Tarifa Neta | G6: Km | H6: Combustible | I6: Mantención | J6: Peajes | K6: Sueldo | L6: Viático | M6: C.Fijo | N6: Continge. | O6: Comisión | P6: Factoring | Q6: Utilidad
A7: San Fernando (solo) | B7: 11 | C7: 1 | D7: =MAX(C7,Supuestos_Presupuesto!$B$21) -> 2 | E7: 549716.4 | F7: =E7+(D7-1)*Supuestos_Presupuesto!$B$22 -> 609716.4 | G7: =Supuestos_Presupuesto!$B$9+(D7-1)*Supuestos_Presupuesto!$B$10 -> 409 | H7: =G7/Supuestos_Presupuesto!$B$11*Supuestos_Presupuesto!$B$12/(1+Supuestos_Presupuesto!$B$4) -> 164974.79 | I7: =G7*Supuestos_Presupuesto!$B$14 -> 10225 | J7: =Supuestos_Presupuesto!$B$13 -> 50000 | K7: =Supuestos_Presupuesto!$B$8*Supuestos_Presupuesto!$B$15 -> 49500 | L7: =Supuestos_Presupuesto!$B$8*Supuestos_Presupuesto!$B$16 -> 18000 | M7: =Supuestos_Presupuesto!$B$8*Supuestos_Presupuesto!$B$23 -> 43750.5 | N7: =Supuestos_Presupuesto!$B$8*Supuestos_Presupuesto!$B$24 -> 37500 | O7: =F7*Supuestos_Presupuesto!$B$17 -> 48777.312 | P7: =F7*(1+Supuestos_Presupuesto!$B$4)*Supuestos_Presupuesto!$B$18 -> 21766.875 | Q7: =F7-SUM(H7:P7) -> 165221.92
A8: Pichidegua (solo) | B8: 8 | C8: 1 | D8: =MAX(C8,Supuestos_Presupuesto!$B$21) -> 2 | E8: 458699.2 | F8: =E8+(D8-1)*Supuestos_Presupuesto!$B$22 -> 518699.2 | G8: =Supuestos_Presupuesto!$B$9+(D8-1)*Supuestos_Presupuesto!$B$10 -> 409 | H8: =G8/Supuestos_Presupuesto!$B$11*Supuestos_Presupuesto!$B$12/(1+Supuestos_Presupuesto!$B$4) -> 164974.79 | I8: =G8*Supuestos_Presupuesto!$B$14 -> 10225 | J8: =Supuestos_Presupuesto!$B$13 -> 50000 | K8: =Supuestos_Presupuesto!$B$8*Supuestos_Presupuesto!$B$15 -> 49500 | L8: =Supuestos_Presupuesto!$B$8*Supuestos_Presupuesto!$B$16 -> 18000 | M8: =Supuestos_Presupuesto!$B$8*Supuestos_Presupuesto!$B$23 -> 43750.5 | N8: =Supuestos_Presupuesto!$B$8*Supuestos_Presupuesto!$B$24 -> 37500 | O8: =F8*Supuestos_Presupuesto!$B$17 -> 41495.936 | P8: =F8*(1+Supuestos_Presupuesto!$B$4)*Supuestos_Presupuesto!$B$18 -> 18517.561 | Q8: =F8-SUM(H8:P8) -> 84735.413
A9: Santa Cruz (solo) | B9: 6 | C9: 1 | D9: =MAX(C9,Supuestos_Presupuesto!$B$21) -> 2 | E9: 470166.68 | F9: =E9+(D9-1)*Supuestos_Presupuesto!$B$22 -> 530166.68 | G9: =Supuestos_Presupuesto!$B$9+(D9-1)*Supuestos_Presupuesto!$B$10 -> 409 | H9: =G9/Supuestos_Presupuesto!$B$11*Supuestos_Presupuesto!$B$12/(1+Supuestos_Presupuesto!$B$4) -> 164974.79 | I9: =G9*Supuestos_Presupuesto!$B$14 -> 10225 | J9: =Supuestos_Presupuesto!$B$13 -> 50000 | K9: =Supuestos_Presupuesto!$B$8*Supuestos_Presupuesto!$B$15 -> 49500 | L9: =Supuestos_Presupuesto!$B$8*Supuestos_Presupuesto!$B$16 -> 18000 | M9: =Supuestos_Presupuesto!$B$8*Supuestos_Presupuesto!$B$23 -> 43750.5 | N9: =Supuestos_Presupuesto!$B$8*Supuestos_Presupuesto!$B$24 -> 37500 | O9: =F9*Supuestos_Presupuesto!$B$17 -> 42413.334 | P9: =F9*(1+Supuestos_Presupuesto!$B$4)*Supuestos_Presupuesto!$B$18 -> 18926.95 | Q9: =F9-SUM(H9:P9) -> 94876.105
A10: San Vicente (solo) | B10: 5 | C10: 1 | D10: =MAX(C10,Supuestos_Presupuesto!$B$21) -> 2 | E10: 516036.6 | F10: =E10+(D10-1)*Supuestos_Presupuesto!$B$22 -> 576036.6 | G10: =Supuestos_Presupuesto!$B$9+(D10-1)*Supuestos_Presupuesto!$B$10 -> 409 | H10: =G10/Supuestos_Presupuesto!$B$11*Supuestos_Presupuesto!$B$12/(1+Supuestos_Presupuesto!$B$4) -> 164974.79 | I10: =G10*Supuestos_Presupuesto!$B$14 -> 10225 | J10: =Supuestos_Presupuesto!$B$13 -> 50000 | K10: =Supuestos_Presupuesto!$B$8*Supuestos_Presupuesto!$B$15 -> 49500 | L10: =Supuestos_Presupuesto!$B$8*Supuestos_Presupuesto!$B$16 -> 18000 | M10: =Supuestos_Presupuesto!$B$8*Supuestos_Presupuesto!$B$23 -> 43750.5 | N10: =Supuestos_Presupuesto!$B$8*Supuestos_Presupuesto!$B$24 -> 37500 | O10: =F10*Supuestos_Presupuesto!$B$17 -> 46082.928 | P10: =F10*(1+Supuestos_Presupuesto!$B$4)*Supuestos_Presupuesto!$B$18 -> 20564.507 | Q10: =F10-SUM(H10:P10) -> 135438.88
A11: Rengo (solo) | B11: 4 | C11: 1 | D11: =MAX(C11,Supuestos_Presupuesto!$B$21) -> 2 | E11: 470166.68 | F11: =E11+(D11-1)*Supuestos_Presupuesto!$B$22 -> 530166.68 | G11: =Supuestos_Presupuesto!$B$9+(D11-1)*Supuestos_Presupuesto!$B$10 -> 409 | H11: =G11/Supuestos_Presupuesto!$B$11*Supuestos_Presupuesto!$B$12/(1+Supuestos_Presupuesto!$B$4) -> 164974.79 | I11: =G11*Supuestos_Presupuesto!$B$14 -> 10225 | J11: =Supuestos_Presupuesto!$B$13 -> 50000 | K11: =Supuestos_Presupuesto!$B$8*Supuestos_Presupuesto!$B$15 -> 49500 | L11: =Supuestos_Presupuesto!$B$8*Supuestos_Presupuesto!$B$16 -> 18000 | M11: =Supuestos_Presupuesto!$B$8*Supuestos_Presupuesto!$B$23 -> 43750.5 | N11: =Supuestos_Presupuesto!$B$8*Supuestos_Presupuesto!$B$24 -> 37500 | O11: =F11*Supuestos_Presupuesto!$B$17 -> 42413.334 | P11: =F11*(1+Supuestos_Presupuesto!$B$4)*Supuestos_Presupuesto!$B$18 -> 18926.95 | Q11: =F11-SUM(H11:P11) -> 94876.105
A12: Peralillo + Santa Cruz | B12: 3 | C12: 2 | D12: =MAX(C12,Supuestos_Presupuesto!$B$21) -> 2 | E12: 470166.68 | F12: =E12+(D12-1)*Supuestos_Presupuesto!$B$22 -> 530166.68 | G12: =Supuestos_Presupuesto!$B$9+(D12-1)*Supuestos_Presupuesto!$B$10 -> 409 | H12: =G12/Supuestos_Presupuesto!$B$11*Supuestos_Presupuesto!$B$12/(1+Supuestos_Presupuesto!$B$4) -> 164974.79 | I12: =G12*Supuestos_Presupuesto!$B$14 -> 10225 | J12: =Supuestos_Presupuesto!$B$13 -> 50000 | K12: =Supuestos_Presupuesto!$B$8*Supuestos_Presupuesto!$B$15 -> 49500 | L12: =Supuestos_Presupuesto!$B$8*Supuestos_Presupuesto!$B$16 -> 18000 | M12: =Supuestos_Presupuesto!$B$8*Supuestos_Presupuesto!$B$23 -> 43750.5 | N12: =Supuestos_Presupuesto!$B$8*Supuestos_Presupuesto!$B$24 -> 37500 | O12: =F12*Supuestos_Presupuesto!$B$17 -> 42413.334 | P12: =F12*(1+Supuestos_Presupuesto!$B$4)*Supuestos_Presupuesto!$B$18 -> 18926.95 | Q12: =F12-SUM(H12:P12) -> 94876.105
A13: San Fernando + Santa Cruz | B13: 3 | C13: 2 | D13: =MAX(C13,Supuestos_Presupuesto!$B$21) -> 2 | E13: 549716.4 | F13: =E13+(D13-1)*Supuestos_Presupuesto!$B$22 -> 609716.4 | G13: =Supuestos_Presupuesto!$B$9+(D13-1)*Supuestos_Presupuesto!$B$10 -> 409 | H13: =G13/Supuestos_Presupuesto!$B$11*Supuestos_Presupuesto!$B$12/(1+Supuestos_Presupuesto!$B$4) -> 164974.79 | I13: =G13*Supuestos_Presupuesto!$B$14 -> 10225 | J13: =Supuestos_Presupuesto!$B$13 -> 50000 | K13: =Supuestos_Presupuesto!$B$8*Supuestos_Presupuesto!$B$15 -> 49500 | L13: =Supuestos_Presupuesto!$B$8*Supuestos_Presupuesto!$B$16 -> 18000 | M13: =Supuestos_Presupuesto!$B$8*Supuestos_Presupuesto!$B$23 -> 43750.5 | N13: =Supuestos_Presupuesto!$B$8*Supuestos_Presupuesto!$B$24 -> 37500 | O13: =F13*Supuestos_Presupuesto!$B$17 -> 48777.312 | P13: =F13*(1+Supuestos_Presupuesto!$B$4)*Supuestos_Presupuesto!$B$18 -> 21766.875 | Q13: =F13-SUM(H13:P13) -> 165221.92
A14: San Fernando + San Vicente + Santa Cruz | B14: 3 | C14: 3 | D14: =MAX(C14,Supuestos_Presupuesto!$B$21) -> 3 | E14: 549716.4 | F14: =E14+(D14-1)*Supuestos_Presupuesto!$B$22 -> 669716.4 | G14: =Supuestos_Presupuesto!$B$9+(D14-1)*Supuestos_Presupuesto!$B$10 -> 459 | H14: =G14/Supuestos_Presupuesto!$B$11*Supuestos_Presupuesto!$B$12/(1+Supuestos_Presupuesto!$B$4) -> 185142.86 | I14: =G14*Supuestos_Presupuesto!$B$14 -> 11475 | J14: =Supuestos_Presupuesto!$B$13 -> 50000 | K14: =Supuestos_Presupuesto!$B$8*Supuestos_Presupuesto!$B$15 -> 49500 | L14: =Supuestos_Presupuesto!$B$8*Supuestos_Presupuesto!$B$16 -> 18000 | M14: =Supuestos_Presupuesto!$B$8*Supuestos_Presupuesto!$B$23 -> 43750.5 | N14: =Supuestos_Presupuesto!$B$8*Supuestos_Presupuesto!$B$24 -> 37500 | O14: =F14*Supuestos_Presupuesto!$B$17 -> 53577.312 | P14: =F14*(1+Supuestos_Presupuesto!$B$4)*Supuestos_Presupuesto!$B$18 -> 23908.875 | Q14: =F14-SUM(H14:P14) -> 196861.86
A15: Peumo + Pichidegua | B15: 3 | C15: 2 | D15: =MAX(C15,Supuestos_Presupuesto!$B$21) -> 2 | E15: 458699.2 | F15: =E15+(D15-1)*Supuestos_Presupuesto!$B$22 -> 518699.2 | G15: =Supuestos_Presupuesto!$B$9+(D15-1)*Supuestos_Presupuesto!$B$10 -> 409 | H15: =G15/Supuestos_Presupuesto!$B$11*Supuestos_Presupuesto!$B$12/(1+Supuestos_Presupuesto!$B$4) -> 164974.79 | I15: =G15*Supuestos_Presupuesto!$B$14 -> 10225 | J15: =Supuestos_Presupuesto!$B$13 -> 50000 | K15: =Supuestos_Presupuesto!$B$8*Supuestos_Presupuesto!$B$15 -> 49500 | L15: =Supuestos_Presupuesto!$B$8*Supuestos_Presupuesto!$B$16 -> 18000 | M15: =Supuestos_Presupuesto!$B$8*Supuestos_Presupuesto!$B$23 -> 43750.5 | N15: =Supuestos_Presupuesto!$B$8*Supuestos_Presupuesto!$B$24 -> 37500 | O15: =F15*Supuestos_Presupuesto!$B$17 -> 41495.936 | P15: =F15*(1+Supuestos_Presupuesto!$B$4)*Supuestos_Presupuesto!$B$18 -> 18517.561 | Q15: =F15-SUM(H15:P15) -> 84735.413
A16: Peralillo (solo) | B16: 3 | C16: 1 | D16: =MAX(C16,Supuestos_Presupuesto!$B$21) -> 2 | E16: 458699.2 | F16: =E16+(D16-1)*Supuestos_Presupuesto!$B$22 -> 518699.2 | G16: =Supuestos_Presupuesto!$B$9+(D16-1)*Supuestos_Presupuesto!$B$10 -> 409 | H16: =G16/Supuestos_Presupuesto!$B$11*Supuestos_Presupuesto!$B$12/(1+Supuestos_Presupuesto!$B$4) -> 164974.79 | I16: =G16*Supuestos_Presupuesto!$B$14 -> 10225 | J16: =Supuestos_Presupuesto!$B$13 -> 50000 | K16: =Supuestos_Presupuesto!$B$8*Supuestos_Presupuesto!$B$15 -> 49500 | L16: =Supuestos_Presupuesto!$B$8*Supuestos_Presupuesto!$B$16 -> 18000 | M16: =Supuestos_Presupuesto!$B$8*Supuestos_Presupuesto!$B$23 -> 43750.5 | N16: =Supuestos_Presupuesto!$B$8*Supuestos_Presupuesto!$B$24 -> 37500 | O16: =F16*Supuestos_Presupuesto!$B$17 -> 41495.936 | P16: =F16*(1+Supuestos_Presupuesto!$B$4)*Supuestos_Presupuesto!$B$18 -> 18517.561 | Q16: =F16-SUM(H16:P16) -> 84735.413
A17: Graneros (solo) | B17: 3 | C17: 1 | D17: =MAX(C17,Supuestos_Presupuesto!$B$21) -> 2 | E17: 424296.76 | F17: =E17+(D17-1)*Supuestos_Presupuesto!$B$22 -> 484296.76 | G17: =Supuestos_Presupuesto!$B$9+(D17-1)*Supuestos_Presupuesto!$B$10 -> 409 | H17: =G17/Supuestos_Presupuesto!$B$11*Supuestos_Presupuesto!$B$12/(1+Supuestos_Presupuesto!$B$4) -> 164974.79 | I17: =G17*Supuestos_Presupuesto!$B$14 -> 10225 | J17: =Supuestos_Presupuesto!$B$13 -> 50000 | K17: =Supuestos_Presupuesto!$B$8*Supuestos_Presupuesto!$B$15 -> 49500 | L17: =Supuestos_Presupuesto!$B$8*Supuestos_Presupuesto!$B$16 -> 18000 | M17: =Supuestos_Presupuesto!$B$8*Supuestos_Presupuesto!$B$23 -> 43750.5 | N17: =Supuestos_Presupuesto!$B$8*Supuestos_Presupuesto!$B$24 -> 37500 | O17: =F17*Supuestos_Presupuesto!$B$17 -> 38743.741 | P17: =F17*(1+Supuestos_Presupuesto!$B$4)*Supuestos_Presupuesto!$B$18 -> 17289.394 | Q17: =F17-SUM(H17:P17) -> 54313.335
A18: Malloa + Rancagua | B18: 2 | C18: 2 | D18: =MAX(C18,Supuestos_Presupuesto!$B$21) -> 2 | E18: 481634.16 | F18: =E18+(D18-1)*Supuestos_Presupuesto!$B$22 -> 541634.16 | G18: =Supuestos_Presupuesto!$B$9+(D18-1)*Supuestos_Presupuesto!$B$10 -> 409 | H18: =G18/Supuestos_Presupuesto!$B$11*Supuestos_Presupuesto!$B$12/(1+Supuestos_Presupuesto!$B$4) -> 164974.79 | I18: =G18*Supuestos_Presupuesto!$B$14 -> 10225 | J18: =Supuestos_Presupuesto!$B$13 -> 50000 | K18: =Supuestos_Presupuesto!$B$8*Supuestos_Presupuesto!$B$15 -> 49500 | L18: =Supuestos_Presupuesto!$B$8*Supuestos_Presupuesto!$B$16 -> 18000 | M18: =Supuestos_Presupuesto!$B$8*Supuestos_Presupuesto!$B$23 -> 43750.5 | N18: =Supuestos_Presupuesto!$B$8*Supuestos_Presupuesto!$B$24 -> 37500 | O18: =F18*Supuestos_Presupuesto!$B$17 -> 43330.733 | P18: =F18*(1+Supuestos_Presupuesto!$B$4)*Supuestos_Presupuesto!$B$18 -> 19336.34 | Q18: =F18-SUM(H18:P18) -> 105016.8
... A21: Marchigüe (solo) | B21: 2 | C21: 1 | D21: =MAX(C21,Supuestos_Presupuesto!$B$21) -> 2 | E21: 458699.2 | F21: =E21+(D21-1)*Supuestos_Presupuesto!$B$22 -> 518699.2 | G21: =Supuestos_Presupuesto!$B$9+(D21-1)*Supuestos_Presupuesto!$B$10 -> 409 | H21: =G21/Supuestos_Presupuesto!$B$11*Supuestos_Presupuesto!$B$12/(1+Supuestos_Presupuesto!$B$4) -> 164974.79 | I21: =G21*Supuestos_Presupuesto!$B$14 -> 10225 | J21: =Supuestos_Presupuesto!$B$13 -> 50000 | K21: =Supuestos_Presupuesto!$B$8*Supuestos_Presupuesto!$B$15 -> 49500 | L21: =Supuestos_Presupuesto!$B$8*Supuestos_Presupuesto!$B$16 -> 18000 | M21: =Supuestos_Presupuesto!$B$8*Supuestos_Presupuesto!$B$23 -> 43750.5 | N21: =Supuestos_Presupuesto!$B$8*Supuestos_Presupuesto!$B$24 -> 37500 | O21: =F21*Supuestos_Presupuesto!$B$17 -> 41495.936 | P21: =F21*(1+Supuestos_Presupuesto!$B$4)*Supuestos_Presupuesto!$B$18 -> 18517.561 | Q21: =F21-SUM(H21:P21) -> 84735.413
A22: PROMEDIO PONDERADO POR FRECUENCIA | B22: =SUM(B7:B21) -> 60 | D22: =SUMPRODUCT($B$7:$B$21,D7:D21)/B22 -> 2.0833333 | F22: =SUMPRODUCT($B$7:$B$21,F7:F21)/B22 -> 557705.77 | G22: =SUMPRODUCT($B$7:$B$21,G7:G21)/B22 -> 413.16667 | Q22: =SUMPRODUCT($B$7:$B$21,Q7:Q21)/B22 -> 117444.08
A24: Ingreso Neto (ventas, tarifa+puntos promedio ponderado real) | B24: =Supuestos_Presupuesto!$B$19*Supuestos_Presupuesto!$B$7*F22 -> 14500350 | C24: =Supuestos_Presupuesto!$B$20*Supuestos_Presupuesto!$B$7*F22 -> 21750525
A25: IVA Débito Fiscal (19%, informativo) | B25: =B24*Supuestos_Presupuesto!$B$4 -> 2755066.5 | C25: =C24*Supuestos_Presupuesto!$B$4 -> 4132599.7
A26: Ingreso Bruto (facturado) | B26: =B24*(1+Supuestos_Presupuesto!$B$4) -> 17255416 | C26: =C24*(1+Supuestos_Presupuesto!$B$4) -> 25883125
A28: COSTOS OPERACIONALES DIRECTOS (netos, sin IVA salvo que se indique)
A29: Combustible (neto — precio de bomba÷1,19) | B29: =Supuestos_Presupuesto!$B$19*Supuestos_Presupuesto!$B$7*G22/Supuestos_Presupuesto!$B$11*Supuestos_Presupuesto!$B$12/(1+Supuestos_Presupuesto!$B$4) -> 4333042 | C29: =Supuestos_Presupuesto!$B$20*Supuestos_Presupuesto!$B$7*G22/Supuestos_Presupuesto!$B$11*Supuestos_Presupuesto!$B$12/(1+Supuestos_Presupuesto!$B$4) -> 6499563
A30: Peajes (flat/servicio, exento IVA) | B30: =Supuestos_Presupuesto!$B$19*Supuestos_Presupuesto!$B$7*Supuestos_Presupuesto!$B$13 -> 1300000 | C30: =Supuestos_Presupuesto!$B$20*Supuestos_Presupuesto!$B$7*Supuestos_Presupuesto!$B$13 -> 1950000
A31: Mantención (neto) | B31: =Supuestos_Presupuesto!$B$19*Supuestos_Presupuesto!$B$7*G22*Supuestos_Presupuesto!$B$14 -> 268558.33 | C31: =Supuestos_Presupuesto!$B$20*Supuestos_Presupuesto!$B$7*G22*Supuestos_Presupuesto!$B$14 -> 402837.5
A32: Sueldo Conductor | B32: =Supuestos_Presupuesto!$B$19*Supuestos_Presupuesto!$B$7*Supuestos_Presupuesto!$B$8*Supuestos_Presupuesto!$B$15 -> 1287000 | C32: =Supuestos_Presupuesto!$B$20*Supuestos_Presupuesto!$B$7*Supuestos_Presupuesto!$B$8*Supuestos_Presupuesto!$B$15 -> 1930500
A33: Viático | B33: =Supuestos_Presupuesto!$B$19*Supuestos_Presupuesto!$B$7*Supuestos_Presupuesto!$B$8*Supuestos_Presupuesto!$B$16 -> 468000 | C33: =Supuestos_Presupuesto!$B$20*Supuestos_Presupuesto!$B$7*Supuestos_Presupuesto!$B$8*Supuestos_Presupuesto!$B$16 -> 702000
A34: Comisión Conductor | B34: =B24*Supuestos_Presupuesto!$B$17 -> 1160028 | C34: =C24*Supuestos_Presupuesto!$B$17 -> 1740042
A35: Contingencia | B35: =Supuestos_Presupuesto!$B$19*Supuestos_Presupuesto!$B$7*Supuestos_Presupuesto!$B$8*Supuestos_Presupuesto!$B$24 -> 975000 | C35: =Supuestos_Presupuesto!$B$20*Supuestos_Presupuesto!$B$7*Supuestos_Presupuesto!$B$8*Supuestos_Presupuesto!$B$24 -> 1462500
A36: Costo Fijo Equipo (real, evidencia Kaptura) | B36: =Supuestos_Presupuesto!$B$19*Supuestos_Presupuesto!$B$7*Supuestos_Presupuesto!$B$8*Supuestos_Presupuesto!$B$23 -> 1137513 | C36: =Supuestos_Presupuesto!$B$20*Supuestos_Presupuesto!$B$7*Supuestos_Presupuesto!$B$8*Supuestos_Presupuesto!$B$23 -> 1706269.5
A37: Total Costos Operacionales Directos | B37: =B29+B30+B31+B32+B33+B34+B35+B36 -> 10929141 | C37: =C29+C30+C31+C32+C33+C34+C35+C36 -> 16393712
A38: Combustible pagado (bruto, cash) | B38: =Supuestos_Presupuesto!$B$19*Supuestos_Presupuesto!$B$7*G22/Supuestos_Presupuesto!$B$11*Supuestos_Presupuesto!$B$12 -> 5156320 | C38: =Supuestos_Presupuesto!$B$20*Supuestos_Presupuesto!$B$7*G22/Supuestos_Presupuesto!$B$11*Supuestos_Presupuesto!$B$12 -> 7734480
A40: MARGEN DIRECTO (Ingreso Neto − Costos Directos) | B40: =B24-B37 -> 3571208.6 | C40: =C24-C37 -> 5356812.9
A41: Factoring (3% sobre tarifa BRUTA) | B41: =B24*(1+Supuestos_Presupuesto!$B$4)*Supuestos_Presupuesto!$B$18 -> 517662.49 | C41: =C24*(1+Supuestos_Presupuesto!$B$4)*Supuestos_Presupuesto!$B$18 -> 776493.74
A42: MARGEN DIRECTO NETO DE FACTORING | B42: =B40-B41 -> 3053546.1 | C42: =C40-C41 -> 4580319.2
A44: COSTEO POR KM (metodología de mercado: Costo Fijo + Costo Variable)
A45: Km Totales del Mes | B45: =Supuestos_Presupuesto!$B$19*Supuestos_Presupuesto!$B$7*G22 -> 10742.333 | C45: =Supuestos_Presupuesto!$B$20*Supuestos_Presupuesto!$B$7*G22 -> 16113.5
A46: Costo Fijo por Km (Costo Fijo Equipo ÷ Km) | B46: =B36/B45 -> 105.89068 | C46: =C36/C45 -> 105.89068
A47: Costo Variable por Km (Combustible+Mantención+Peajes ÷ Km) | B47: =(B29+B31+B30)/B45 -> 549.37788 | C47: =(C29+C31+C30)/C45 -> 549.37788
...

Sheet TRAST
A1: TRAST — INGRESO, COSTOS DIRECTOS Y MARGEN (Agosto vs. Septiembre)
A3: Concepto | B3: Agosto | C3: Septiembre
A4: Ingreso Neto (ventas) | B4: =Supuestos_Presupuesto!$B$39*Supuestos_Presupuesto!$B$38*Supuestos_Presupuesto!$B$27 -> 10207768 | C4: =Supuestos_Presupuesto!$B$40*Supuestos_Presupuesto!$B$38*Supuestos_Presupuesto!$B$27 -> 10207768
A5: IVA Débito Fiscal (19%, informativo) | B5: =B4*Supuestos_Presupuesto!$B$4 -> 1939475.9 | C5: =C4*Supuestos_Presupuesto!$B$4 -> 1939475.9
A6: Ingreso Bruto (facturado) | B6: =B4*(1+Supuestos_Presupuesto!$B$4) -> 12147244 | C6: =C4*(1+Supuestos_Presupuesto!$B$4) -> 12147244
A8: COSTOS OPERACIONALES DIRECTOS (netos, sin IVA salvo que se indique)
A9: Combustible (neto — precio de bomba÷1,19) | B9: =Supuestos_Presupuesto!$B$39*Supuestos_Presupuesto!$B$38*Supuestos_Presupuesto!$B$28/(1+Supuestos_Presupuesto!$B$4) -> 2403361.3 | C9: =Supuestos_Presupuesto!$B$40*Supuestos_Presupuesto!$B$38*Supuestos_Presupuesto!$B$28/(1+Supuestos_Presupuesto!$B$4) -> 2403361.3
A10: Peajes (exento IVA) | B10: =Supuestos_Presupuesto!$B$39*Supuestos_Presupuesto!$B$38*Supuestos_Presupuesto!$B$31 -> 1426440 | C10: =Supuestos_Presupuesto!$B$40*Supuestos_Presupuesto!$B$38*Supuestos_Presupuesto!$B$31 -> 1426440
A11: Mantención (neto) | B11: =Supuestos_Presupuesto!$B$39*Supuestos_Presupuesto!$B$38*Supuestos_Presupuesto!$B$29 -> 190690 | C11: =Supuestos_Presupuesto!$B$40*Supuestos_Presupuesto!$B$38*Supuestos_Presupuesto!$B$29 -> 190690
A12: Sueldo Conductor | B12: =Supuestos_Presupuesto!$B$39*Supuestos_Presupuesto!$B$38*Supuestos_Presupuesto!$B$32 -> 660000 | C12: =Supuestos_Presupuesto!$B$40*Supuestos_Presupuesto!$B$38*Supuestos_Presupuesto!$B$32 -> 660000
A13: Viático | B13: =Supuestos_Presupuesto!$B$39*Supuestos_Presupuesto!$B$38*Supuestos_Presupuesto!$B$33 -> 240000 | C13: =Supuestos_Presupuesto!$B$40*Supuestos_Presupuesto!$B$38*Supuestos_Presupuesto!$B$33 -> 240000
A14: Comisión Conductor | B14: =Supuestos_Presupuesto!$B$39*Supuestos_Presupuesto!$B$38*Supuestos_Presupuesto!$B$35 -> 816620 | C14: =Supuestos_Presupuesto!$B$40*Supuestos_Presupuesto!$B$38*Supuestos_Presupuesto!$B$35 -> 816620
A15: Provisión Reparaciones | B15: =Supuestos_Presupuesto!$B$39*Supuestos_Presupuesto!$B$38*Supuestos_Presupuesto!$B$30 -> 500000 | C15: =Supuestos_Presupuesto!$B$40*Supuestos_Presupuesto!$B$38*Supuestos_Presupuesto!$B$30 -> 500000
A16: Costo Fijo Equipo | B16: =Supuestos_Presupuesto!$B$39*Supuestos_Presupuesto!$B$38*Supuestos_Presupuesto!$B$34 -> 720000 | C16: =Supuestos_Presupuesto!$B$40*Supuestos_Presupuesto!$B$38*Supuestos_Presupuesto!$B$34 -> 720000
A17: Total Costos Operacionales Directos | B17: =B9+B10+B11+B12+B13+B14+B15+B16 -> 6957111.3 | C17: =C9+C10+C11+C12+C13+C14+C15+C16 -> 6957111.3
A18: Combustible pagado (bruto, cash) | B18: =Supuestos_Presupuesto!$B$39*Supuestos_Presupuesto!$B$38*Supuestos_Presupuesto!$B$28 -> 2860000 | C18: =Supuestos_Presupuesto!$B$40*Supuestos_Presupuesto!$B$38*Supuestos_Presupuesto!$B$28 -> 2860000
A20: MARGEN DIRECTO (Ingreso Neto − Costos Directos) | B20: =B4-B17 -> 3250656.7 | C20: =C4-C17 -> 3250656.7
A21: Factoring | B21: =B4*Supuestos_Presupuesto!$B$36 -> 153116.52 | C21: =C4*Supuestos_Presupuesto!$B$36 -> 153116.52
A22: MARGEN DIRECTO NETO DE FACTORING | B22: =B20-B21 -> 3097540.1 | C22: =C20-C21 -> 3097540.1
A24: COSTEO POR KM (metodología de mercado: Costo Fijo + Costo Variable)
A25: Km Totales del Mes | B25: =Supuestos_Presupuesto!$B$39*Supuestos_Presupuesto!$B$38*715 -> 7150 | C25: =Supuestos_Presupuesto!$B$40*Supuestos_Presupuesto!$B$38*715 -> 7150
A26: Costo Fijo por Km (Costo Fijo Equipo ÷ Km) | B26: =B16/B25 -> 100.6993 | C26: =C16/C25 -> 100.6993
A27: Costo Variable por Km (Combustible+Mantención+Peajes ÷ Km) | B27: =(B9+B11+B10)/B25 -> 562.30648 | C27: =(C9+C11+C10)/C25 -> 562.30648
A28: Costo por Km de Conductor (Sueldo+Viático+Comisión ÷ Km) | B28: =(B12+B13+B14)/B25 -> 240.08671 | C28: =(C12+C13+C14)/C25 -> 240.08671
A29: Provisión Fondo Reserva/Reparaciones por Km | B29: =B15/B25 -> 69.93007 | C29: =C15/C25 -> 69.93007
A30: COSTO TOTAL POR KM | B30: =B17/B25 -> 973.02257 | C30: =C17/C25 -> 973.02257
A31: Tarifa por Km efectiva (Ingreso Neto ÷ Km) | B31: =B4/B25 -> 1427.6599 | C31: =C4/C25 -> 1427.6599
A32: Margen por Km (Tarifa/Km − Costo Total/Km) | B32: =B31-B30 -> 454.63729 | C32: =C31-C30 -> 454.63729
A34: MEMORIA DE CÁLCULO
A35: Ingreso Neto = lo que realmente factura el cliente (sin IVA). Ingreso Bruto = lo que efectivamente se deposita en el banco (Neto × 1,19). El margen se calcula SIEMPRE sobre Neto — el IVA no es ingreso ni costo real, es un impuesto de paso.
A36: Combustible: el precio de $1.200/lt YA incluye IVA (precio de bomba). Para el margen (neto) se divide por 1,19; para caja se paga el bruto completo (fila de referencia 'Combustible pagado').
A37: Peajes y Provisión de Fondo de Reserva/Reparaciones no llevan IVA (no son compras facturadas por terceros).
A38: Factoring se calcula sobre el Ingreso Bruto realmente descontado por la entidad de factoring (dato real observado en Kaptura), y se resta DESPUÉS del margen directo porque es un costo financiero, no operacional.
A39: Todas las celdas de esta hoja son fórmulas ligadas a 'Supuestos_Presupuesto' — cambiar un supuesto ahí recalcula todo.

Sheet Consolidado
A1: CONSOLIDADO — SOLLEM + TRAST (Estado de Resultados y Flujo de Caja)
A3: Concepto | B3: Agosto | C3: Septiembre
A4: ESTADO DE RESULTADOS (base neta, sin IVA)
A5: Ingreso Neto (ventas) | B5: =Sollem!B24+TRAST!B4 -> 24708118 | C5: =Sollem!C24+TRAST!C4 -> 31958293
A6: IVA Débito Fiscal (19%, informativo) | B6: =B5*Supuestos_Presupuesto!$B$4 -> 4694542.4 | C6: =C5*Supuestos_Presupuesto!$B$4 -> 6072075.7
A7: Ingreso Bruto (facturado) | B7: =B5*(1+Supuestos_Presupuesto!$B$4) -> 29402660 | C7: =C5*(1+Supuestos_Presupuesto!$B$4) -> 38030369
A9: Total Costos Operacionales Directos (Sollem+TRAST) | B9: =Sollem!B37+TRAST!B17 -> 17886253 | C9: =Sollem!C37+TRAST!C17 -> 23350823
A10: MARGEN DIRECTO | B10: =B5-B9 -> 6821865.3 | C10: =C5-C9 -> 8607469.6
A11: Factoring (Sollem+TRAST) | B11: =Sollem!B41+TRAST!B21 -> 670779.01 | C11: =Sollem!C41+TRAST!C21 -> 929610.26
A12: Margen Directo neto de Factoring | B12: =B10-B11 -> 6151086.2 | C12: =C10-C11 -> 7677859.3
A14: COSTOS DE ESTRUCTURA (no atribuibles a un cliente)
A15: Costo fijo estructural | B15: =Supuestos_Presupuesto!$B$44 -> 3940000 | C15: =Supuestos_Presupuesto!$B$44 -> 3940000
A16: Costo Cuenta Corriente Bancaria | B16: =Supuestos_Presupuesto!$B$43 -> 9000 | C16: =Supuestos_Presupuesto!$B$43 -> 9000
A18: UTILIDAD ANTES DE IMPUESTOS | B18: =B12-B15-B16 -> 2202086.2 | C18: =C12-C15-C16 -> 3728859.3
A19: % Utilidad / Ingreso Bruto | B19: =B18/B7 -> 0.074894116 | C19: =C18/C7 -> 0.098049518
A21: TOTAL EGRESOS DE CAJA DEL MES (base bruta/cash — para el flujo semanal)
A22: Total Egresos de Caja del Mes | B22: =(Sollem!B37-Sollem!B29+Sollem!B38)+(TRAST!B17-TRAST!B9+TRAST!B18)+B11+B15+B16+Supuestos_Presupuesto!$B$45 -> 26439095 | C22: =(Sollem!C37-Sollem!C29+Sollem!C38)+(TRAST!C17-TRAST!C9+TRAST!C18)+C11+C15+C16+Supuestos_Presupuesto!$B$46 -> 33074136
A24: FLUJO DE CAJA PROYECTADO — AGOSTO (por semana, calendario real)
A25: Semana | B25: Ingreso | C25: Egreso | D25: Saldo Semana | E25: Acumulado
A26: S0 (01-02 ago) | B26: =$B$7*0 -> 0 | C26: =$B$22*0.156171505182074 -> 4129033.3 | D26: =B26-C26 -> -4129033.3 | E26: =D26 -> -4129033.3
A27: S1 (03-09 ago) | B27: =$B$7*0.238095235026902 -> 7000633.3 | C27: =$B$22*0.255737503422307 -> 6761468.2 | D27: =B27-C27 -> 239165.09 | E27: =E26+D27 -> -3889868.2
A28: S2 (10-16 ago) | B28: =$B$7*0.238095235026902 -> 7000633.3 | C28: =$B$22*0.199837319041854 -> 5283517.9 | D28: =B28-C28 -> 1717115.4 | E28: =E27+D28 -> -2172752.8
A29: S3 (17-23 ago) | B29: =$B$7*0.238095235026902 -> 7000633.3 | C29: =$B$22*0.134064675251262 -> 3544548.7 | D29: =B29-C29 -> 3456084.6 | E29: =E28+D29 -> 1283331.8
A30: S4 (24-30 ago) | B30: =$B$7*0.238095235026902 -> 7000633.3 | C30: =$B$22*0.114192256574636 -> 3019140 | D30: =B30-C30 -> 3981493.4 | E30: =E29+D30 -> 5264825.1
A31: S5 (31 ago) | B31: =$B$7*0.0476190598923934 -> 1400127 | C31: =$B$22*0.139996740527866 -> 3701387.2 | D31: =B31-C31 -> -2301260.1 | E31: =E30+D31 -> 2963565
A32: TOTAL | B32: =SUM(B26:B31) -> 29402660 | C32: =SUM(C26:C31) -> 26439095 | D32: =SUM(D26:D31) -> 2963565
A34: FLUJO DE CAJA PROYECTADO — SEPTIEMBRE (por semana, calendario real)
A35: Semana | B35: Ingreso | C35: Egreso | D35: Saldo Semana | E35: Acumulado
A36: S0 (01-06 sep) | B36: =$C$7*0.181818181818182 -> 6914612.5 | C36: =$C$22*0.369048345284379 -> 12205955 | D36: =B36-C36 -> -5291342.8 | E36: =D36 -> -5291342.8
A37: S1 (07-13 sep) | B37: =$C$7*0.227272727272727 -> 8643265.6 | C37: =$C$22*0.193903403264155 -> 6413187.6 | D37: =B37-C37 -> 2230078 | E37: =E36+D37 -> -3061264.8
A38: S2 (14-20 sep) | B38: =$C$7*0.227272727272727 -> 8643265.6 | C38: =$C$22*0.136643242485644 -> 4519357.2 | D38: =B38-C38 -> 4123908.4 | E38: =E37+D38 -> 1062643.6
A39: S3 (21-27 sep) | B39: =$C$7*0.227272727272727 -> 8643265.6 | C39: =$C$22*0.115715129398367 -> 3827178 | D39: =B39-C39 -> 4816087.6 | E39: =E38+D39 -> 5878731.2
A40: S4 (28-30 sep) | B40: =$C$7*0.136363636363636 -> 5185959.4 | C40: =$C$22*0.184689879567455 -> 6108458.2 | D40: =B40-C40 -> -922498.89 | E40: =E39+D40 -> 4956232.3
A41: TOTAL | B41: =SUM(B36:B40) -> 38030369 | C41: =SUM(C36:C40) -> 33074136 | D41: =SUM(D36:D40) -> 4956232.3
A43: MEMORIA DE CÁLCULO Y SUPUESTOS
A44: El Estado de Resultados usa SIEMPRE valores netos (sin IVA) — es la utilidad real del negocio. El Flujo de Caja usa valores brutos (con IVA) — es lo que efectivamente entra y sale del banco. No son el mismo número y no deberían confundirse: el Ingreso Bruto incluye ~19% de IVA que no es ganancia, es plata que hay que devolverle al Fisco (por eso existe la línea IVA a pagar, con un mes de desfase).
A45: Costos de Estructura (Costo fijo estructural, Costo Cuenta Corriente) no se dividen entre Sollem y TRAST porque no dependen de qué cliente se atienda — son costos de la empresa completa.
A46: El Flujo de Caja Semanal reparte el Ingreso Bruto y el Egreso de Caja del mes usando los mismos porcentajes semanales que tenía el archivo original (reflejan el calendario real de pagos: IVA, liquidaciones, anticipos) — si cambia el calendario real de pagos, estos porcentajes hay que revisarlos a mano.
A47: IVA a pagar en el Flujo de Caja es el del MES ANTERIOR (desfase real de un mes) — dato manual en Supuestos_Presupuesto, no depende de los supuestos del mes actual.
A48: Detalle línea por línea de cada cliente (Sollem, TRAST) está en sus propias hojas — esta hoja solo consolida.

Sheet Conciliación_Junio
A1: CONCILIACIÓN BANCARIA — JUNIO 2026 (Global Solutions SPA, cuenta 0-000-3776731-0)
A2: Fuente: Cartola histórica N°2 (29/05 al 30/06/2026) + RCV Compra/Venta SII período 202606.
A4: A) VENTAS (RCV) vs ABONOS EN CARTOLA
A5: Cliente | B5: Folio | C5: Fecha Factura | D5: Monto Neto | E5: IVA | F5: Monto Total | G5: Estado | H5: Observación
A6: SOLLEM SPA | B6: 1 | C6: 02-06-2026 | D6: 1868400 | E6: 354996 | F6: 2223396 | G6: Factorizada | H6: Factoring confirmado (Sollem se factoriza 100% — validado con Kaptura/Supabase).
A7: TECNOLOGIA Y SERVICIOS LOSKO LIMITADA | B7: 2 | C7: 06-06-2026 | D7: 280000 | E7: 53200 | F7: 333200 | G7: Sin identificar | H7: No hay abono directo por este monto en la cartola — posible factoring u otro medio, o pago aún pendiente.
A8: SOLLEM SPA | B8: 3 | C8: 09-06-2026 | D8: 3550400 | E8: 674576 | F8: 4224976 | G8: Factorizada | H8: Factoring confirmado (Sollem se factoriza 100% — validado con Kaptura/Supabase).
A9: SERVICIOS LOGISTICOS INTEGRALES SPA | B9: 4 | C9: 09-06-2026 | D9: 991200 | E9: 188328 | F9: 1179528 | G9: Sin identificar | H9: No hay abono directo por este monto en la cartola — posible factoring u otro medio, o pago aún pendiente.
A10: AGRICOLA Y PACKING CACHAPOAL S A | B10: 5 | C10: 15-06-2026 | D10: 324000 | E10: 61560 | F10: 385560 | G10: Sin identificar | H10: No hay abono directo por este monto en la cartola — posible factoring u otro medio, o pago aún pendiente.
A11: AGRICOLA GEORUCA SPA | B11: 7 | C11: 15-06-2026 | D11: 300000 | E11: 57000 | F11: 357000 | G11: Sin identificar | H11: No hay abono directo por este monto en la cartola — posible factoring u otro medio, o pago aún pendiente.
A12: SERVICIOS LOGISTICOS INTEGRALES SPA | B12: 8 | C12: 15-06-2026 | D12: 330400 | E12: 62776 | F12: 393176 | G12: Sin identificar | H12: No hay abono directo por este monto en la cartola — posible factoring u otro medio, o pago aún pendiente.
A13: INVERSIONES Y ASESORIAS CITRUS LIMITADA | B13: 9 | C13: 15-06-2026 | D13: 660800 | E13: 125552 | F13: 786352 | G13: Sin identificar | H13: No hay abono directo por este monto en la cartola — posible factoring u otro medio, o pago aún pendiente.
A14: ANDONI LUCIANO SANDOVAL PAVEZ | B14: 11 | C14: 22-06-2026 | D14: 600000 | E14: 114000 | F14: 714000 | G14: Sin identificar | H14: No hay abono directo por este monto en la cartola — posible factoring u otro medio, o pago aún pendiente.
A15: AGRICOLA Y COMERCIAL EL ENANO SPA | B15: 12 | C15: 22-06-2026 | D15: 490000 | E15: 93100 | F15: 583100 | G15: Sin identificar | H15: No hay abono directo por este monto en la cartola — posible factoring u otro medio, o pago aún pendiente.
A16: SOLLEM SPA | B16: 13 | C16: 24-06-2026 | D16: 2355000 | E16: 447450 | F16: 2802450 | G16: Factorizada | H16: Factoring confirmado (Sollem se factoriza 100% — validado con Kaptura/Supabase).
A17: SOCIEDAD DE TRANSPORTE SANTA BERENICE SPA | B17: 15 | C17: 26-06-2026 | D17: 370000 | E17: 70300 | F17: 440300 | G17: Sin identificar | H17: No hay abono directo por este monto en la cartola — posible factoring u otro medio, o pago aún pendiente.
... A19: SERVICIOS LOGISTICOS INTEGRALES SPA | B19: 1 | C19: 15-06-2026 | D19: 991200 | E19: 188328 | F19: 1179528 | G19: Sin identificar | H19: No hay abono directo por este monto en la cartola — posible factoring u otro medio, o pago aún pendiente.
A20: TOTAL VENTAS RCV | F20: 16410814 | G20: Identificado: 0 de 14 ($0 de $16,410,814)
A22: B) COMPRAS (RCV) vs CARGOS EN CARTOLA
A23: Proveedor (RUT) | B23: Folio | C23: Fecha Factura | D23: Monto Neto | E23: IVA | F23: Monto Total | G23: Estado | H23: Observación
A24: 79588870-5 | B24: 2733997 | C24: 01-06-2026 | D24: 1528427 | E24: 290401 | F24: 2000000 | G24: Pagada | H24: Cargo cartola 01-06-2026 — PAGO EN LINEA ESMAX
A25: 77400268-5 | B25: 2446 | C25: 29-05-2026 | D25: 6050 | E25: 1150 | F25: 7200 | G25: Sin identificar | H25: No hay cargo por este monto exacto en la cartola — revisar si se pagó en otra fecha/cuenta o si sigue pendiente.
A26: 77398220-1 | B26: 13690952 | C26: 01-06-2026 | D26: 25538 | E26: 4852 | F26: 30390 | G26: Sin identificar | H26: No hay cargo por este monto exacto en la cartola — revisar si se pagó en otra fecha/cuenta o si sigue pendiente.
A27: 96907830-9 | B27: 1844288 | C27: 02-06-2026 | D27: 85621 | E27: 16268 | F27: 101889 | G27: Sin identificar | H27: No hay cargo por este monto exacto en la cartola — revisar si se pagó en otra fecha/cuenta o si sigue pendiente.
A28: 76197149-2 | B28: 731182 | C28: 02-06-2026 | D28: 12605 | E28: 2395 | F28: 15000 | G28: Pagada | H28: Cargo cartola 02-06-2026 — 0142013436 Transf a Felipe Madaria
A29: 96511460-2 | B29: 22769192 | C29: 03-06-2026 | D29: 1182683 | E29: 224710 | F29: 1407393 | G29: Sin identificar | H29: No hay cargo por este monto exacto en la cartola — revisar si se pagó en otra fecha/cuenta o si sigue pendiente.
A30: 77400268-5 | B30: 2480 | C30: 03-06-2026 | D30: 67412 | E30: 12808 | F30: 80220 | G30: Sin identificar | H30: No hay cargo por este monto exacto en la cartola — revisar si se pagó en otra fecha/cuenta o si sigue pendiente.
A31: 77400268-5 | B31: 2491 | C31: 04-06-2026 | D31: 4529 | E31: 861 | F31: 5390 | G31: Sin identificar | H31: No hay cargo por este monto exacto en la cartola — revisar si se pagó en otra fecha/cuenta o si sigue pendiente.
A32: 77400268-5 | B32: 2494 | C32: 05-06-2026 | D32: 605 | E32: 115 | F32: 720 | G32: Sin identificar | H32: No hay cargo por este monto exacto en la cartola — revisar si se pagó en otra fecha/cuenta o si sigue pendiente.
A33: 9094801-6 | B33: 10619 | C33: 06-06-2026 | D33: 315546 | E33: 59954 | F33: 375500 | G33: Sin identificar | H33: No hay cargo por este monto exacto en la cartola — revisar si se pagó en otra fecha/cuenta o si sigue pendiente.
A34: 77400268-5 | B34: 2511 | C34: 08-06-2026 | D34: 2815 | E34: 535 | F34: 3350 | G34: Sin identificar | H34: No hay cargo por este monto exacto en la cartola — revisar si se pagó en otra fecha/cuenta o si sigue pendiente.
A35: 77400268-5 | B35: 2510 | C35: 08-06-2026 | D35: 6723 | E35: 1277 | F35: 8000 | G35: Sin identificar | H35: No hay cargo por este monto exacto en la cartola — revisar si se pagó en otra fecha/cuenta o si sigue pendiente.
... A93: 96511460-2 | B93: 13973319 | C93: 19-06-2026 | D93: 57828 | E93: 10987 | F93: 68815 | G93: Sin identificar | H93: No hay cargo por este monto exacto en la cartola — revisar si se pagó en otra fecha/cuenta o si sigue pendiente.
A94: TOTAL COMPRAS RCV | F94: 12619605 | G94: Identificado: 25 de 70 ($8,568,601)
A96: C) MOVIMIENTOS DE CARTOLA SIN FACTURA RCV ASOCIADA (clasificados)
A97: Fecha | B97: Descripción | C97: Monto | D97: Cargo/Abono | E97: Clasificación
A98: 01-06-2026 | B98: 0783031345 Transf. GLOBAL SOLUTION | C98: 4000000 | D98: A | E98: Transferencia interna Global Solutions
A99: 01-06-2026 | B99: 0783031345 Transf. GLOBAL SOLUTION | C99: 70000 | D99: A | E99: Transferencia interna Global Solutions
A100: 01-06-2026 | B100: Abono Ventas GETNET 29/05/26 CIERR | C100: 277 | D100: A | E100: Venta POS/Tarjeta (no es factura RCV)
A101: 01-06-2026 | B101: 0175018409 Transf a Felipe Vidal | C101: -100000 | D101: C | E101: Transferencia conductor/personal
...

Sheet Conciliación_Julio
A1: CONCILIACIÓN BANCARIA — JULIO 2026 (Global Solutions SPA, cartola completa al 29-07-2026)
A2: Fuente: Cartola de movimientos completa (01/07 al 29/07/2026, 131 movimientos) + RCV Compra/Venta SII período 202607. Mes en curso (faltan 2 días hábiles), repetir con la cartola de cierre de mes.
A4: A) VENTAS (RCV) vs ABONOS EN CARTOLA
A5: Cliente | B5: Folio | C5: Fecha Factura | D5: Monto Neto | E5: IVA | F5: Monto Total | G5: Estado | H5: Observación
A6: LOGÍSTICA Y TRANSPORTES ALFA JAM SPA | B6: 19 | C6: 01-07-2026 | D6: 370000 | E6: 70300 | F6: 440300 | G6: Pagada | H6: Abono cartola 09-07-2026 — 0780993812 Transf. LOGISTICA Y TRANSPORTES A
A7: SOLLEM SPA | B7: 20 | C7: 15-07-2026 | D7: 1818400 | E7: 345496 | F7: 2163896 | G7: Factorizada | H7: Factoring confirmado (Sollem se factoriza 100% — validado con Kaptura/Supabase).
A8: SOLLEM SPA | B8: 22 | C8: 21-07-2026 | D8: 2006400 | E8: 381216 | F8: 2387616 | G8: Factorizada | H8: Factoring confirmado (Sollem se factoriza 100% — validado con Kaptura/Supabase).
A9: DANILO ENRIQUE NUNEZ OSORIO | B9: 24 | C9: 25-07-2026 | D9: 580000 | E9: 110200 | F9: 690200 | G9: Sin identificar | H9: No hay abono directo por este monto en la cartola — posible factoring u otro medio, o pago aún pendiente.
A10: SOCIEDAD DE TRANSPORTE SANTA BERENICE SPA | B10: 2 | C10: 01-07-2026 | D10: 370000 | E10: 70300 | F10: 440300 | G10: Sin identificar | H10: No hay abono directo por este monto en la cartola — posible factoring u otro medio, o pago aún pendiente.
A11: TOTAL VENTAS RCV | F11: 6122312 | G11: Identificado: 1 de 5 ($440,300 de $6,122,312)
A13: B) COMPRAS (RCV) vs CARGOS EN CARTOLA
A14: Proveedor (RUT) | B14: Folio | C14: Fecha Factura | D14: Monto Neto | E14: IVA | F14: Monto Total | G14: Estado | H14: Observación
A15: 76307389-0 | B15: 319591 | C15: 01-07-2026 | D15: 17017 | E15: 3233 | F15: 20250 | G15: Sin identificar | H15: No hay cargo por este monto exacto en la cartola — revisar si se pagó en otra fecha/cuenta o si sigue pendiente.
A16: 76307389-0 | B16: 319592 | C16: 01-07-2026 | D16: 10168 | E16: 1932 | F16: 12100 | G16: Sin identificar | H16: No hay cargo por este monto exacto en la cartola — revisar si se pagó en otra fecha/cuenta o si sigue pendiente.
A17: 79588870-5 | B17: 2745962 | C17: 01-07-2026 | D17: 892481 | E17: 169572 | F17: 1300000 | G17: Pagada | H17: Cargo cartola 01-07-2026 — PAGO EN LINEA ESMAX
A18: 76630639-K | B18: 4071 | C18: 02-07-2026 | D18: 25210 | E18: 4790 | F18: 30000 | G18: Pagada | H18: Cargo cartola 02-07-2026 — 076630639K Transf a Servicios integrales FYR
A19: 77400268-5 | B19: 2666 | C19: 02-07-2026 | D19: 19061 | E19: 3622 | F19: 22683 | G19: Sin identificar | H19: No hay cargo por este monto exacto en la cartola — revisar si se pagó en otra fecha/cuenta o si sigue pendiente.
A20: 79703410-K | B20: 299681 | C20: 02-07-2026 | D20: 251770 | E20: 47836 | F20: 299606 | G20: Pagada | H20: Cargo cartola 03-07-2026 — COMERCIAL RIHE LTDA
A21: 79703410-K | B21: 299686 | C21: 02-07-2026 | D21: 18674 | E21: 3548 | F21: 22222 | G21: Sin identificar | H21: No hay cargo por este monto exacto en la cartola — revisar si se pagó en otra fecha/cuenta o si sigue pendiente.
A22: 77460910-5 | B22: 552096 | C22: 02-07-2026 | D22: 77600 | E22: 14744 | F22: 92344 | G22: Pagada | H22: Cargo cartola 03-07-2026 — Compra Nacional MD VALPAR LTDA.
A23: 78924030-2 | B23: 6711841 | C23: 02-07-2026 | D23: 15109 | E23: 2871 | F23: 17980 | G23: Pagada | H23: Cargo cartola 03-07-2026 — IMPLEMENTOS S.A.
A24: 99581430-7 | B24: 1150357 | C24: 02-07-2026 | D24: 66387 | E24: 12614 | F24: 79001 | G24: Sin identificar | H24: No hay cargo por este monto exacto en la cartola — revisar si se pagó en otra fecha/cuenta o si sigue pendiente.
A25: 99520000-7 | B25: 32107271 | C25: 02-07-2026 | D25: 8403 | E25: 1597 | F25: 10000 | G25: Sin identificar | H25: No hay cargo por este monto exacto en la cartola — revisar si se pagó en otra fecha/cuenta o si sigue pendiente.
A26: 99520000-7 | B26: 32124365 | C26: 03-07-2026 | D26: 29418 | E26: 5590 | F26: 41580 | G26: Sin identificar | H26: No hay cargo por este monto exacto en la cartola — revisar si se pagó en otra fecha/cuenta o si sigue pendiente.
... A63: 77400268-5 | B63: 357 | C63: 13-07-2026 | D63: 20124 | E63: 3824 | F63: 23948 | G63: Sin identificar | H63: No hay cargo por este monto exacto en la cartola — revisar si se pagó en otra fecha/cuenta o si sigue pendiente.
A64: TOTAL COMPRAS RCV | F64: 8677299 | G64: Identificado: 28 de 49 ($6,200,514)
A66: C) MOVIMIENTOS DE CARTOLA SIN FACTURA RCV ASOCIADA (clasificados)
A67: Fecha | B67: Descripción | C67: Monto | D67: Cargo/Abono | E67: Clasificación
A68: 01-07-2026 | B68: 0175018409 Transf a Felipe Vidal | C68: -27000 | D68: C | E68: Transferencia conductor/personal
A69: 01-07-2026 | B69: 0783031345 Transf. GLOBAL SOLUTIONS SPA | C69: 2326472 | D69: A | E69: Transferencia interna Global Solutions
A70: 01-07-2026 | B70: 0159957802 Transf a RIQUELME OLEA PABLO | C70: -70000 | D70: C | E70: Transferencia conductor/personal
A71: 01-07-2026 | B71: 0175018409 Transf a Felipe Vidal | C71: -6000 | D71: C | E71: Transferencia conductor/personal
A72: 02-07-2026 | B72: TUU*COMERCIAL ESCORPIO | C72: -2700 | D72: C | E72: Otro / revisar manualmente
A73: 02-07-2026 | B73: 0175020268 Transf a Nicolás Carvallo | C73: -190000 | D73: C | E73: Transferencia conductor/personal
A74: 02-07-2026 | B74: 0119944848 Transf a José Acevedo | C74: -54000 | D74: C | E74: Transferencia conductor/personal
A75: 02-07-2026 | B75: 0168844255 Transf a Sebastián Zúñiga | C75: -225000 | D75: C | E75: Transferencia conductor/personal
A76: 03-07-2026 | B76: 0175018409 Transf a Felipe Vidal | C76: -17000 | D76: C | E76: Transferencia conductor/personal
A77: 03-07-2026 | B77: 0772906366 Transf. SERVICIOS EL ENANO SPA | C77: 83100 | D77: A | E77: Otro / revisar manualmente
A78: 03-07-2026 | B78: 0776497649 Transf. COMERCIALIZADORA Y PR | C78: 270000 | D78: A | E78: Otro / revisar manualmente
A79: 03-07-2026 | B79: 0197068833 Transf a Felipe Tapia Diez | C79: -280000 | D79: C | E79: Transferencia conductor/personal
...

Sheet Real_vs_Presupuesto
A1: CONTROL DE CUMPLIMIENTO — REAL vs. PRESUPUESTO Y FLUJO DE CAJA
A2: Proyectado se vincula a la hoja Consolidado (flujo de caja semanal, base bruta/cash). Real (amarillo) se completa cada semana con la conciliación bancaria.
A4: CONTROL SEMANAL — AGOSTO (Consolidado)
A5: Semana | B5: Ingreso Proyectado | C5: Ingreso Real | D5: Diferencia Ingreso | E5: Egreso Proyectado | F5: Egreso Real | G5: Diferencia Egreso | H5: Saldo Proyectado | I5: Saldo Real | J5: ¿Cumplió? | K5: Causa (si no cumplió) / Corrección propuesta
A6: =Consolidado!A26 -> S0 (01-02 ago) | B6: =Consolidado!B26 -> 0 | D6: =IF(C6="","",C6-B6) | E6: =Consolidado!C26 -> 4129033.3 | G6: =IF(F6="","",F6-E6) | H6: =Consolidado!D26 -> -4129033.3 | I6: =IF(OR(C6="",F6=""),"",C6-F6) | J6: =IF(I6="","Pendiente",IF(I6>=H6,"Sí","No")) -> Pendiente
A7: =Consolidado!A27 -> S1 (03-09 ago) | B7: =Consolidado!B27 -> 7000633.3 | D7: =IF(C7="","",C7-B7) | E7: =Consolidado!C27 -> 6761468.2 | G7: =IF(F7="","",F7-E7) | H7: =Consolidado!D27 -> 239165.09 | I7: =IF(OR(C7="",F7=""),"",C7-F7) | J7: =IF(I7="","Pendiente",IF(I7>=H7,"Sí","No")) -> Pendiente
A8: =Consolidado!A28 -> S2 (10-16 ago) | B8: =Consolidado!B28 -> 7000633.3 | D8: =IF(C8="","",C8-B8) | E8: =Consolidado!C28 -> 5283517.9 | G8: =IF(F8="","",F8-E8) | H8: =Consolidado!D28 -> 1717115.4 | I8: =IF(OR(C8="",F8=""),"",C8-F8) | J8: =IF(I8="","Pendiente",IF(I8>=H8,"Sí","No")) -> Pendiente
A9: =Consolidado!A29 -> S3 (17-23 ago) | B9: =Consolidado!B29 -> 7000633.3 | D9: =IF(C9="","",C9-B9) | E9: =Consolidado!C29 -> 3544548.7 | G9: =IF(F9="","",F9-E9) | H9: =Consolidado!D29 -> 3456084.6 | I9: =IF(OR(C9="",F9=""),"",C9-F9) | J9: =IF(I9="","Pendiente",IF(I9>=H9,"Sí","No")) -> Pendiente
A10: =Consolidado!A30 -> S4 (24-30 ago) | B10: =Consolidado!B30 -> 7000633.3 | D10: =IF(C10="","",C10-B10) | E10: =Consolidado!C30 -> 3019140 | G10: =IF(F10="","",F10-E10) | H10: =Consolidado!D30 -> 3981493.4 | I10: =IF(OR(C10="",F10=""),"",C10-F10) | J10: =IF(I10="","Pendiente",IF(I10>=H10,"Sí","No")) -> Pendiente
A11: =Consolidado!A31 -> S5 (31 ago) | B11: =Consolidado!B31 -> 1400127 | D11: =IF(C11="","",C11-B11) | E11: =Consolidado!C31 -> 3701387.2 | G11: =IF(F11="","",F11-E11) | H11: =Consolidado!D31 -> -2301260.1 | I11: =IF(OR(C11="",F11=""),"",C11-F11) | J11: =IF(I11="","Pendiente",IF(I11>=H11,"Sí","No")) -> Pendiente
A13: CONTROL SEMANAL — SEPTIEMBRE (Consolidado)
A14: Semana | B14: Ingreso Proyectado | C14: Ingreso Real | D14: Diferencia Ingreso | E14: Egreso Proyectado | F14: Egreso Real | G14: Diferencia Egreso | H14: Saldo Proyectado | I14: Saldo Real | J14: ¿Cumplió? | K14: Causa (si no cumplió) / Corrección propuesta
A15: =Consolidado!A36 -> S0 (01-06 sep) | B15: =Consolidado!B36 -> 6914612.5 | D15: =IF(C15="","",C15-B15) | E15: =Consolidado!C36 -> 12205955 | G15: =IF(F15="","",F15-E15) | H15: =Consolidado!D36 -> -5291342.8 | I15: =IF(OR(C15="",F15=""),"",C15-F15) | J15: =IF(I15="","Pendiente",IF(I15>=H15,"Sí","No")) -> Pendiente
A16: =Consolidado!A37 -> S1 (07-13 sep) | B16: =Consolidado!B37 -> 8643265.6 | D16: =IF(C16="","",C16-B16) | E16: =Consolidado!C37 -> 6413187.6 | G16: =IF(F16="","",F16-E16) | H16: =Consolidado!D37 -> 2230078 | I16: =IF(OR(C16="",F16=""),"",C16-F16) | J16: =IF(I16="","Pendiente",IF(I16>=H16,"Sí","No")) -> Pendiente
A17: =Consolidado!A38 -> S2 (14-20 sep) | B17: =Consolidado!B38 -> 8643265.6 | D17: =IF(C17="","",C17-B17) | E17: =Consolidado!C38 -> 4519357.2 | G17: =IF(F17="","",F17-E17) | H17: =Consolidado!D38 -> 4123908.4 | I17: =IF(OR(C17="",F17=""),"",C17-F17) | J17: =IF(I17="","Pendiente",IF(I17>=H17,"Sí","No")) -> Pendiente
A18: =Consolidado!A39 -> S3 (21-27 sep) | B18: =Consolidado!B39 -> 8643265.6 | D18: =IF(C18="","",C18-B18) | E18: =Consolidado!C39 -> 3827178 | G18: =IF(F18="","",F18-E18) | H18: =Consolidado!D39 -> 4816087.6 | I18: =IF(OR(C18="",F18=""),"",C18-F18) | J18: =IF(I18="","Pendiente",IF(I18>=H18,"Sí","No")) -> Pendiente
A19: =Consolidado!A40 -> S4 (28-30 sep) | B19: =Consolidado!B40 -> 5185959.4 | D19: =IF(C19="","",C19-B19) | E19: =Consolidado!C40 -> 6108458.2 | G19: =IF(F19="","",F19-E19) | H19: =Consolidado!D40 -> -922498.89 | I19: =IF(OR(C19="",F19=""),"",C19-F19) | J19: =IF(I19="","Pendiente",IF(I19>=H19,"Sí","No")) -> Pendiente

Sheet Resumen_Ejecutivo
A1: RESUMEN EJECUTIVO
A3: INFORME DE RESULTADOS FINANCIEROS (Estado de Resultados, base neta sin IVA)
A4: Concepto | B4: Agosto 2026 | C4: Septiembre 2026
A5: Ingreso Neto (ventas) | B5: =Consolidado!B5 -> 24708118 | C5: =Consolidado!C5 -> 31958293
A6: IVA Débito Fiscal (informativo) | B6: =Consolidado!B6 -> 4694542.4 | C6: =Consolidado!C6 -> 6072075.7
A7: Ingreso Bruto (facturado) | B7: =Consolidado!B7 -> 29402660 | C7: =Consolidado!C7 -> 38030369
A8: Total Costos Operacionales Directos | B8: =Consolidado!B9 -> 17886253 | C8: =Consolidado!C9 -> 23350823
A9: Margen Directo | B9: =Consolidado!B10 -> 6821865.3 | C9: =Consolidado!C10 -> 8607469.6
A10: Factoring | B10: =Consolidado!B11 -> 670779.01 | C10: =Consolidado!C11 -> 929610.26
A11: Margen Directo neto de Factoring | B11: =Consolidado!B12 -> 6151086.2 | C11: =Consolidado!C12 -> 7677859.3
A12: Costo fijo estructural | B12: =Consolidado!B15 -> 3940000 | C12: =Consolidado!C15 -> 3940000
A13: Costo Cuenta Corriente Bancaria | B13: =Consolidado!B16 -> 9000 | C13: =Consolidado!C16 -> 9000
A14: UTILIDAD ANTES DE IMPUESTOS | B14: =Consolidado!B18 -> 2202086.2 | C14: =Consolidado!C18 -> 3728859.3
A15: % Utilidad / Ingreso Bruto | B15: =Consolidado!B19 -> 0.074894116 | C15: =Consolidado!C19 -> 0.098049518
A17: Este informe usa valores NETOS (sin IVA) — es la utilidad real, distinta del Saldo de caja semanal (que incluye IVA cobrado, aún no pagado al Fisco). Ver hoja Consolidado para el detalle completo.
A20: PLAN vs. REAL vs. REPROYECCIÓN (flujo de caja semanal)
A21: Tomado de Real_vs_Presupuesto. Reproyección Fin de Mes = Real acumulado + Presupuesto de semanas sin dato real.
A22: AGOSTO 2026
A23: Concepto | B23: Presupuesto Mensual (caja) | C23: Real Acumulado | D23: Semanas con dato real | E23: Presupuesto de lo que falta | F23: Reproyección Fin de Mes | G23: % Cumplimiento
A24: Ingreso (bruto, caja) | B24: =Consolidado!B32 -> 29402660 | C24: =SUM(Real_vs_Presupuesto!C6:C11) -> 0 | D24: =COUNT(Real_vs_Presupuesto!C6:C11)&" de 6" -> 0 de 6 | E24: =SUMIF(Real_vs_Presupuesto!C6:C11,"",Real_vs_Presupuesto!B6:B11) -> 29402660 | F24: =C24+E24 -> 29402660 | G24: =F24/B24 -> 1
A25: Egreso (bruto, caja) | B25: =Consolidado!C32 -> 26439095 | C25: =SUM(Real_vs_Presupuesto!F6:F11) -> 0 | D25: =COUNT(Real_vs_Presupuesto!F6:F11)&" de 6" -> 0 de 6 | E25: =SUMIF(Real_vs_Presupuesto!F6:F11,"",Real_vs_Presupuesto!E6:E11) -> 26439095 | F25: =C25+E25 -> 26439095 | G25: =F25/B25 -> 1
A26: Saldo (Ingreso − Egreso) | B26: =B24-B25 -> 2963565 | C26: =C24-C25 -> 0 | E26: =E24-E25 -> 2963565 | F26: =F24-F25 -> 2963565
A28: SEPTIEMBRE 2026
A29: Concepto | B29: Presupuesto Mensual (caja) | C29: Real Acumulado | D29: Semanas con dato real | E29: Presupuesto de lo que falta | F29: Reproyección Fin de Mes | G29: % Cumplimiento
A30: Ingreso (bruto, caja) | B30: =Consolidado!B41 -> 38030369 | C30: =SUM(Real_vs_Presupuesto!C15:C19) -> 0 | D30: =COUNT(Real_vs_Presupuesto!C15:C19)&" de 5" -> 0 de 5 | E30: =SUMIF(Real_vs_Presupuesto!C15:C19,"",Real_vs_Presupuesto!B15:B19) -> 38030369 | F30: =C30+E30 -> 38030369 | G30: =F30/B30 -> 1
A31: Egreso (bruto, caja) | B31: =Consolidado!C41 -> 33074136 | C31: =SUM(Real_vs_Presupuesto!F15:F19) -> 0 | D31: =COUNT(Real_vs_Presupuesto!F15:F19)&" de 5" -> 0 de 5 | E31: =SUMIF(Real_vs_Presupuesto!F15:F19,"",Real_vs_Presupuesto!E15:E19) -> 33074136 | F31: =C31+E31 -> 33074136 | G31: =F31/B31 -> 1
A32: Saldo (Ingreso − Egreso) | B32: =B30-B31 -> 4956232.3 | C32: =C30-C31 -> 0 | E32: =E30-E31 -> 4956232.3 | F32: =F30-F31 -> 4956232.3

Sheet Bitácora_Saldo_Diario
A1: BITÁCORA DE SALDO DIARIO — Banco Santander 0-000-3776731-0
A2: Registro diario del "Saldo de Cuentas Corrientes" (reporte simple, sin movimientos). Alerta temprana: compara el saldo real contra el Saldo Acumulado que proyecta Consolidado para esa semana. Al cierre de cada semana, esto se cruza con la conciliación completa (Conciliación_Junio/Julio como plantilla) — la bitácora es la alerta, la conciliación semanal es la confirmación con facturas.
A4: Fecha | B4: Saldo Disponible (real, del reporte) | C4: Semana Consolidado | D4: Saldo Acumulado Proyectado | E4: Diferencia | F4: Observación
A5: 29-07-2026 | B5: 63371 | C5: Julio (fuera de Consolidado, mes en curso pre-agosto) | F5: Saldo real del 29-07-2026, cartola completa conciliada. Punto de partida de la bitácora.
E6: =IF(OR(B6="",D6=""),"",B6-D6)
E7: =IF(OR(B7="",D7=""),"",B7-D7)
E8: =IF(OR(B8="",D8=""),"",B8-D8)
E9: =IF(OR(B9="",D9=""),"",B9-D9)
E10: =IF(OR(B10="",D10=""),"",B10-D10)
E11: =IF(OR(B11="",D11=""),"",B11-D11)
E12: =IF(OR(B12="",D12=""),"",B12-D12)
E13: =IF(OR(B13="",D13=""),"",B13-D13)
E14: =IF(OR(B14="",D14=""),"",B14-D14)
E15: =IF(OR(B15="",D15=""),"",B15-D15)
E16: =IF(OR(B16="",D16=""),"",B16-D16)
E17: =IF(OR(B17="",D17=""),"",B17-D17)
... E30: =IF(OR(B30="",D30=""),"",B30-D30)
